2022-09-23 09:53:44,077 -  nornir.core -     INFO -        run() - Running task 'pyez_rpc' with args {'func': 'get-system-memory-information'} on 2 hosts
2022-09-23 09:54:14,110 - nornir.core.task -    ERROR -      start() - Host 'mx960-2': task 'pyez_rpc' failed with traceback:
Traceback (most recent call last):
  File "/Users/sohanr/PycharmProjects/Nornir_Auto/venv/lib/python3.9/site-packages/jnpr/junos/device.py", line 1362, in open
    self._conn = netconf_ssh.connect(
  File "/Users/sohanr/PycharmProjects/Nornir_Auto/venv/lib/python3.9/site-packages/ncclient/manager.py", line 176, in connect
    return connect_ssh(*args, **kwds)
  File "/Users/sohanr/PycharmProjects/Nornir_Auto/venv/lib/python3.9/site-packages/ncclient/manager.py", line 143, in connect_ssh
    session.connect(*args, **kwds)
  File "/Users/sohanr/PycharmProjects/Nornir_Auto/venv/lib/python3.9/site-packages/ncclient/transport/ssh.py", line 293, in connect
    raise SSHError("Could not open socket to %s:%s" % (host, port))
ncclient.transport.errors.SSHError: Could not open socket to 10.13.111.2:830

During handling of the above exception, another exception occurred:

Traceback (most recent call last):
  File "/Users/sohanr/PycharmProjects/Nornir_Auto/venv/lib/python3.9/site-packages/nornir/core/task.py", line 99, in start
    r = self.task(self, **self.params)
  File "/Users/sohanr/PycharmProjects/Nornir_Auto/venv/lib/python3.9/site-packages/nornir_pyez/plugins/tasks/pyez_rpc.py", line 16, in pyez_rpc
    device = task.host.get_connection(CONNECTION_NAME, task.nornir.config)
  File "/Users/sohanr/PycharmProjects/Nornir_Auto/venv/lib/python3.9/site-packages/nornir/core/inventory.py", line 494, in get_connection
    self.open_connection(
  File "/Users/sohanr/PycharmProjects/Nornir_Auto/venv/lib/python3.9/site-packages/nornir/core/inventory.py", line 546, in open_connection
    conn_obj.open(
  File "/Users/sohanr/PycharmProjects/Nornir_Auto/venv/lib/python3.9/site-packages/nornir_pyez/plugins/connections/__init__.py", line 41, in open
    connection.open()
  File "/Users/sohanr/PycharmProjects/Nornir_Auto/venv/lib/python3.9/site-packages/jnpr/junos/device.py", line 1401, in open
    raise EzErrors.ConnectTimeoutError(self)
jnpr.junos.exception.ConnectTimeoutError: ConnectTimeoutError(10.13.111.2)

2022-09-23 09:54:14,111 - nornir.core.task -    ERROR -      start() - Host 'mx960-1': task 'pyez_rpc' failed with traceback:
Traceback (most recent call last):
  File "/Users/sohanr/PycharmProjects/Nornir_Auto/venv/lib/python3.9/site-packages/jnpr/junos/device.py", line 1362, in open
    self._conn = netconf_ssh.connect(
  File "/Users/sohanr/PycharmProjects/Nornir_Auto/venv/lib/python3.9/site-packages/ncclient/manager.py", line 176, in connect
    return connect_ssh(*args, **kwds)
  File "/Users/sohanr/PycharmProjects/Nornir_Auto/venv/lib/python3.9/site-packages/ncclient/manager.py", line 143, in connect_ssh
    session.connect(*args, **kwds)
  File "/Users/sohanr/PycharmProjects/Nornir_Auto/venv/lib/python3.9/site-packages/ncclient/transport/ssh.py", line 293, in connect
    raise SSHError("Could not open socket to %s:%s" % (host, port))
ncclient.transport.errors.SSHError: Could not open socket to 10.13.111.18:830

During handling of the above exception, another exception occurred:

Traceback (most recent call last):
  File "/Users/sohanr/PycharmProjects/Nornir_Auto/venv/lib/python3.9/site-packages/nornir/core/task.py", line 99, in start
    r = self.task(self, **self.params)
  File "/Users/sohanr/PycharmProjects/Nornir_Auto/venv/lib/python3.9/site-packages/nornir_pyez/plugins/tasks/pyez_rpc.py", line 16, in pyez_rpc
    device = task.host.get_connection(CONNECTION_NAME, task.nornir.config)
  File "/Users/sohanr/PycharmProjects/Nornir_Auto/venv/lib/python3.9/site-packages/nornir/core/inventory.py", line 494, in get_connection
    self.open_connection(
  File "/Users/sohanr/PycharmProjects/Nornir_Auto/venv/lib/python3.9/site-packages/nornir/core/inventory.py", line 546, in open_connection
    conn_obj.open(
  File "/Users/sohanr/PycharmProjects/Nornir_Auto/venv/lib/python3.9/site-packages/nornir_pyez/plugins/connections/__init__.py", line 41, in open
    connection.open()
  File "/Users/sohanr/PycharmProjects/Nornir_Auto/venv/lib/python3.9/site-packages/jnpr/junos/device.py", line 1401, in open
    raise EzErrors.ConnectTimeoutError(self)
jnpr.junos.exception.ConnectTimeoutError: ConnectTimeoutError(10.13.111.18)

2022-09-23 10:47:47,021 -  nornir.core -     INFO -        run() - Running task 'pyez_rpc' with args {'func': 'get-system-memory-information'} on 2 hosts
2022-09-23 10:48:17,058 - nornir.core.task -    ERROR -      start() - Host 'mx960-1': task 'pyez_rpc' failed with traceback:
Traceback (most recent call last):
  File "/Users/sohanr/PycharmProjects/Nornir_Auto/venv/lib/python3.9/site-packages/jnpr/junos/device.py", line 1362, in open
    self._conn = netconf_ssh.connect(
  File "/Users/sohanr/PycharmProjects/Nornir_Auto/venv/lib/python3.9/site-packages/ncclient/manager.py", line 176, in connect
    return connect_ssh(*args, **kwds)
  File "/Users/sohanr/PycharmProjects/Nornir_Auto/venv/lib/python3.9/site-packages/ncclient/manager.py", line 143, in connect_ssh
    session.connect(*args, **kwds)
  File "/Users/sohanr/PycharmProjects/Nornir_Auto/venv/lib/python3.9/site-packages/ncclient/transport/ssh.py", line 293, in connect
    raise SSHError("Could not open socket to %s:%s" % (host, port))
ncclient.transport.errors.SSHError: Could not open socket to 10.13.111.18:830

During handling of the above exception, another exception occurred:

Traceback (most recent call last):
  File "/Users/sohanr/PycharmProjects/Nornir_Auto/venv/lib/python3.9/site-packages/nornir/core/task.py", line 99, in start
    r = self.task(self, **self.params)
  File "/Users/sohanr/PycharmProjects/Nornir_Auto/venv/lib/python3.9/site-packages/nornir_pyez/plugins/tasks/pyez_rpc.py", line 16, in pyez_rpc
    device = task.host.get_connection(CONNECTION_NAME, task.nornir.config)
  File "/Users/sohanr/PycharmProjects/Nornir_Auto/venv/lib/python3.9/site-packages/nornir/core/inventory.py", line 494, in get_connection
    self.open_connection(
  File "/Users/sohanr/PycharmProjects/Nornir_Auto/venv/lib/python3.9/site-packages/nornir/core/inventory.py", line 546, in open_connection
    conn_obj.open(
  File "/Users/sohanr/PycharmProjects/Nornir_Auto/venv/lib/python3.9/site-packages/nornir_pyez/plugins/connections/__init__.py", line 41, in open
    connection.open()
  File "/Users/sohanr/PycharmProjects/Nornir_Auto/venv/lib/python3.9/site-packages/jnpr/junos/device.py", line 1401, in open
    raise EzErrors.ConnectTimeoutError(self)
jnpr.junos.exception.ConnectTimeoutError: ConnectTimeoutError(10.13.111.18)

2022-09-23 10:48:17,058 - nornir.core.task -    ERROR -      start() - Host 'mx960-2': task 'pyez_rpc' failed with traceback:
Traceback (most recent call last):
  File "/Users/sohanr/PycharmProjects/Nornir_Auto/venv/lib/python3.9/site-packages/jnpr/junos/device.py", line 1362, in open
    self._conn = netconf_ssh.connect(
  File "/Users/sohanr/PycharmProjects/Nornir_Auto/venv/lib/python3.9/site-packages/ncclient/manager.py", line 176, in connect
    return connect_ssh(*args, **kwds)
  File "/Users/sohanr/PycharmProjects/Nornir_Auto/venv/lib/python3.9/site-packages/ncclient/manager.py", line 143, in connect_ssh
    session.connect(*args, **kwds)
  File "/Users/sohanr/PycharmProjects/Nornir_Auto/venv/lib/python3.9/site-packages/ncclient/transport/ssh.py", line 293, in connect
    raise SSHError("Could not open socket to %s:%s" % (host, port))
ncclient.transport.errors.SSHError: Could not open socket to 10.13.111.2:830

During handling of the above exception, another exception occurred:

Traceback (most recent call last):
  File "/Users/sohanr/PycharmProjects/Nornir_Auto/venv/lib/python3.9/site-packages/nornir/core/task.py", line 99, in start
    r = self.task(self, **self.params)
  File "/Users/sohanr/PycharmProjects/Nornir_Auto/venv/lib/python3.9/site-packages/nornir_pyez/plugins/tasks/pyez_rpc.py", line 16, in pyez_rpc
    device = task.host.get_connection(CONNECTION_NAME, task.nornir.config)
  File "/Users/sohanr/PycharmProjects/Nornir_Auto/venv/lib/python3.9/site-packages/nornir/core/inventory.py", line 494, in get_connection
    self.open_connection(
  File "/Users/sohanr/PycharmProjects/Nornir_Auto/venv/lib/python3.9/site-packages/nornir/core/inventory.py", line 546, in open_connection
    conn_obj.open(
  File "/Users/sohanr/PycharmProjects/Nornir_Auto/venv/lib/python3.9/site-packages/nornir_pyez/plugins/connections/__init__.py", line 41, in open
    connection.open()
  File "/Users/sohanr/PycharmProjects/Nornir_Auto/venv/lib/python3.9/site-packages/jnpr/junos/device.py", line 1401, in open
    raise EzErrors.ConnectTimeoutError(self)
jnpr.junos.exception.ConnectTimeoutError: ConnectTimeoutError(10.13.111.2)

2022-09-23 15:34:21,899 -  nornir.core -     INFO -        run() - Running task 'pyez_facts' with args {} on 2 hosts
2022-09-23 15:34:51,941 - nornir.core.task -    ERROR -      start() - Host 'mx960-2': task 'pyez_facts' failed with traceback:
Traceback (most recent call last):
  File "/Users/sohanr/PycharmProjects/Nornir_Auto/venv/lib/python3.9/site-packages/jnpr/junos/device.py", line 1362, in open
    self._conn = netconf_ssh.connect(
  File "/Users/sohanr/PycharmProjects/Nornir_Auto/venv/lib/python3.9/site-packages/ncclient/manager.py", line 176, in connect
    return connect_ssh(*args, **kwds)
  File "/Users/sohanr/PycharmProjects/Nornir_Auto/venv/lib/python3.9/site-packages/ncclient/manager.py", line 143, in connect_ssh
    session.connect(*args, **kwds)
  File "/Users/sohanr/PycharmProjects/Nornir_Auto/venv/lib/python3.9/site-packages/ncclient/transport/ssh.py", line 293, in connect
    raise SSHError("Could not open socket to %s:%s" % (host, port))
ncclient.transport.errors.SSHError: Could not open socket to 10.13.111.2:830

During handling of the above exception, another exception occurred:

Traceback (most recent call last):
  File "/Users/sohanr/PycharmProjects/Nornir_Auto/venv/lib/python3.9/site-packages/nornir/core/task.py", line 99, in start
    r = self.task(self, **self.params)
  File "/Users/sohanr/PycharmProjects/Nornir_Auto/venv/lib/python3.9/site-packages/nornir_pyez/plugins/tasks/pyez_facts.py", line 11, in pyez_facts
    device = task.host.get_connection(CONNECTION_NAME, task.nornir.config)
  File "/Users/sohanr/PycharmProjects/Nornir_Auto/venv/lib/python3.9/site-packages/nornir/core/inventory.py", line 494, in get_connection
    self.open_connection(
  File "/Users/sohanr/PycharmProjects/Nornir_Auto/venv/lib/python3.9/site-packages/nornir/core/inventory.py", line 546, in open_connection
    conn_obj.open(
  File "/Users/sohanr/PycharmProjects/Nornir_Auto/venv/lib/python3.9/site-packages/nornir_pyez/plugins/connections/__init__.py", line 41, in open
    connection.open()
  File "/Users/sohanr/PycharmProjects/Nornir_Auto/venv/lib/python3.9/site-packages/jnpr/junos/device.py", line 1401, in open
    raise EzErrors.ConnectTimeoutError(self)
jnpr.junos.exception.ConnectTimeoutError: ConnectTimeoutError(10.13.111.2)

2022-09-23 15:34:51,941 - nornir.core.task -    ERROR -      start() - Host 'mx960-1': task 'pyez_facts' failed with traceback:
Traceback (most recent call last):
  File "/Users/sohanr/PycharmProjects/Nornir_Auto/venv/lib/python3.9/site-packages/jnpr/junos/device.py", line 1362, in open
    self._conn = netconf_ssh.connect(
  File "/Users/sohanr/PycharmProjects/Nornir_Auto/venv/lib/python3.9/site-packages/ncclient/manager.py", line 176, in connect
    return connect_ssh(*args, **kwds)
  File "/Users/sohanr/PycharmProjects/Nornir_Auto/venv/lib/python3.9/site-packages/ncclient/manager.py", line 143, in connect_ssh
    session.connect(*args, **kwds)
  File "/Users/sohanr/PycharmProjects/Nornir_Auto/venv/lib/python3.9/site-packages/ncclient/transport/ssh.py", line 293, in connect
    raise SSHError("Could not open socket to %s:%s" % (host, port))
ncclient.transport.errors.SSHError: Could not open socket to 10.13.111.18:830

During handling of the above exception, another exception occurred:

Traceback (most recent call last):
  File "/Users/sohanr/PycharmProjects/Nornir_Auto/venv/lib/python3.9/site-packages/nornir/core/task.py", line 99, in start
    r = self.task(self, **self.params)
  File "/Users/sohanr/PycharmProjects/Nornir_Auto/venv/lib/python3.9/site-packages/nornir_pyez/plugins/tasks/pyez_facts.py", line 11, in pyez_facts
    device = task.host.get_connection(CONNECTION_NAME, task.nornir.config)
  File "/Users/sohanr/PycharmProjects/Nornir_Auto/venv/lib/python3.9/site-packages/nornir/core/inventory.py", line 494, in get_connection
    self.open_connection(
  File "/Users/sohanr/PycharmProjects/Nornir_Auto/venv/lib/python3.9/site-packages/nornir/core/inventory.py", line 546, in open_connection
    conn_obj.open(
  File "/Users/sohanr/PycharmProjects/Nornir_Auto/venv/lib/python3.9/site-packages/nornir_pyez/plugins/connections/__init__.py", line 41, in open
    connection.open()
  File "/Users/sohanr/PycharmProjects/Nornir_Auto/venv/lib/python3.9/site-packages/jnpr/junos/device.py", line 1401, in open
    raise EzErrors.ConnectTimeoutError(self)
jnpr.junos.exception.ConnectTimeoutError: ConnectTimeoutError(10.13.111.18)

2022-09-23 15:36:24,666 -  nornir.core -     INFO -        run() - Running task 'pyez_facts' with args {} on 2 hosts
2022-09-23 16:02:01,342 -  nornir.core -     INFO -        run() - Running task 'pyez_facts' with args {} on 2 hosts
2022-09-23 16:04:10,154 -  nornir.core -     INFO -        run() - Running task 'pyez_facts' with args {} on 2 hosts
2022-09-23 16:08:06,708 -  nornir.core -     INFO -        run() - Running task 'pyez_facts' with args {} on 2 hosts
2022-09-23 16:11:34,261 -  nornir.core -     INFO -        run() - Running task 'pyez_facts' with args {} on 2 hosts
2022-09-23 16:21:32,157 -  nornir.core -     INFO -        run() - Running task 'pyez_rpc' with args {'func': 'get-system-alarm-information'} on 2 hosts
2022-09-23 16:23:48,304 -  nornir.core -     INFO -        run() - Running task 'pyez_rpc' with args {'func': 'get-system-alarm-information'} on 3 hosts
2022-09-23 16:24:37,844 -  nornir.core -     INFO -        run() - Running task 'pyez_rpc' with args {'func': 'get-system-alarm-information'} on 3 hosts
2022-09-23 16:33:40,733 -  nornir.core -     INFO -        run() - Running task 'pyez_cmd' with args {'command': 'show chassis alarms | display xml'} on 3 hosts
2022-09-23 16:33:44,550 - nornir.core.task -    ERROR -      start() - Host 'mx960-2': task 'pyez_cmd' failed with traceback:
Traceback (most recent call last):
  File "/Users/sohanr/PycharmProjects/Nornir_Auto/venv/lib/python3.9/site-packages/nornir/core/task.py", line 99, in start
    r = self.task(self, **self.params)
  File "/Users/sohanr/PycharmProjects/Nornir_Auto/venv/lib/python3.9/site-packages/nornir_pyez/plugins/tasks/pyez_cmd.py", line 10, in pyez_cmd
    with StartShell(device) as sh:
  File "/Users/sohanr/PycharmProjects/Nornir_Auto/venv/lib/python3.9/site-packages/jnpr/junos/utils/start_shell.py", line 202, in __enter__
    self.open()
  File "/Users/sohanr/PycharmProjects/Nornir_Auto/venv/lib/python3.9/site-packages/jnpr/junos/utils/start_shell.py", line 128, in open
    self.wait_for(_SHELL_PROMPT)
  File "/Users/sohanr/PycharmProjects/Nornir_Auto/venv/lib/python3.9/site-packages/jnpr/junos/utils/start_shell.py", line 81, in wait_for
    if isinstance(data, bytes):
UnboundLocalError: local variable 'data' referenced before assignment

2022-09-23 16:33:44,550 - nornir.core.task -    ERROR -      start() - Host 'mx480-3': task 'pyez_cmd' failed with traceback:
Traceback (most recent call last):
  File "/Users/sohanr/PycharmProjects/Nornir_Auto/venv/lib/python3.9/site-packages/nornir/core/task.py", line 99, in start
    r = self.task(self, **self.params)
  File "/Users/sohanr/PycharmProjects/Nornir_Auto/venv/lib/python3.9/site-packages/nornir_pyez/plugins/tasks/pyez_cmd.py", line 10, in pyez_cmd
    with StartShell(device) as sh:
  File "/Users/sohanr/PycharmProjects/Nornir_Auto/venv/lib/python3.9/site-packages/jnpr/junos/utils/start_shell.py", line 202, in __enter__
    self.open()
  File "/Users/sohanr/PycharmProjects/Nornir_Auto/venv/lib/python3.9/site-packages/jnpr/junos/utils/start_shell.py", line 128, in open
    self.wait_for(_SHELL_PROMPT)
  File "/Users/sohanr/PycharmProjects/Nornir_Auto/venv/lib/python3.9/site-packages/jnpr/junos/utils/start_shell.py", line 81, in wait_for
    if isinstance(data, bytes):
UnboundLocalError: local variable 'data' referenced before assignment

2022-09-23 16:33:44,573 - nornir.core.task -    ERROR -      start() - Host 'mx960-1': task 'pyez_cmd' failed with traceback:
Traceback (most recent call last):
  File "/Users/sohanr/PycharmProjects/Nornir_Auto/venv/lib/python3.9/site-packages/nornir/core/task.py", line 99, in start
    r = self.task(self, **self.params)
  File "/Users/sohanr/PycharmProjects/Nornir_Auto/venv/lib/python3.9/site-packages/nornir_pyez/plugins/tasks/pyez_cmd.py", line 10, in pyez_cmd
    with StartShell(device) as sh:
  File "/Users/sohanr/PycharmProjects/Nornir_Auto/venv/lib/python3.9/site-packages/jnpr/junos/utils/start_shell.py", line 202, in __enter__
    self.open()
  File "/Users/sohanr/PycharmProjects/Nornir_Auto/venv/lib/python3.9/site-packages/jnpr/junos/utils/start_shell.py", line 128, in open
    self.wait_for(_SHELL_PROMPT)
  File "/Users/sohanr/PycharmProjects/Nornir_Auto/venv/lib/python3.9/site-packages/jnpr/junos/utils/start_shell.py", line 81, in wait_for
    if isinstance(data, bytes):
UnboundLocalError: local variable 'data' referenced before assignment

2022-09-23 16:35:40,516 -  nornir.core -     INFO -        run() - Running task 'pyez_cmd' with args {'command': 'show chassis alarms'} on 3 hosts
2022-09-23 16:37:20,550 -  nornir.core -     INFO -        run() - Running task 'pyez_cmd' with args {'command': 'show chassis alarms | display xml'} on 3 hosts
2022-09-23 16:37:35,814 -  nornir.core -     INFO -        run() - Running task 'pyez_cmd' with args {'command': 'show chassis alarms | display xml'} on 3 hosts
2022-09-23 16:37:53,849 -  nornir.core -     INFO -        run() - Running task 'pyez_cmd' with args {'command': 'show chassis alarms | display xml'} on 3 hosts
2022-09-23 16:39:46,121 -  nornir.core -     INFO -        run() - Running task 'pyez_cmd' with args {'command': 'show chassis alarms | display xml'} on 3 hosts
2022-09-23 16:39:52,901 - nornir.core.task -    ERROR -      start() - Host 'mx480-3': task 'pyez_cmd' failed with traceback:
Traceback (most recent call last):
  File "/Users/sohanr/PycharmProjects/Nornir_Auto/venv/lib/python3.9/site-packages/nornir/core/task.py", line 99, in start
    r = self.task(self, **self.params)
  File "/Users/sohanr/PycharmProjects/Nornir_Auto/venv/lib/python3.9/site-packages/nornir_pyez/plugins/tasks/pyez_cmd.py", line 10, in pyez_cmd
    with StartShell(device) as sh:
  File "/Users/sohanr/PycharmProjects/Nornir_Auto/venv/lib/python3.9/site-packages/jnpr/junos/utils/start_shell.py", line 202, in __enter__
    self.open()
  File "/Users/sohanr/PycharmProjects/Nornir_Auto/venv/lib/python3.9/site-packages/jnpr/junos/utils/start_shell.py", line 128, in open
    self.wait_for(_SHELL_PROMPT)
  File "/Users/sohanr/PycharmProjects/Nornir_Auto/venv/lib/python3.9/site-packages/jnpr/junos/utils/start_shell.py", line 81, in wait_for
    if isinstance(data, bytes):
UnboundLocalError: local variable 'data' referenced before assignment

2022-09-23 16:39:52,901 - nornir.core.task -    ERROR -      start() - Host 'mx960-2': task 'pyez_cmd' failed with traceback:
Traceback (most recent call last):
  File "/Users/sohanr/PycharmProjects/Nornir_Auto/venv/lib/python3.9/site-packages/nornir/core/task.py", line 99, in start
    r = self.task(self, **self.params)
  File "/Users/sohanr/PycharmProjects/Nornir_Auto/venv/lib/python3.9/site-packages/nornir_pyez/plugins/tasks/pyez_cmd.py", line 10, in pyez_cmd
    with StartShell(device) as sh:
  File "/Users/sohanr/PycharmProjects/Nornir_Auto/venv/lib/python3.9/site-packages/jnpr/junos/utils/start_shell.py", line 202, in __enter__
    self.open()
  File "/Users/sohanr/PycharmProjects/Nornir_Auto/venv/lib/python3.9/site-packages/jnpr/junos/utils/start_shell.py", line 128, in open
    self.wait_for(_SHELL_PROMPT)
  File "/Users/sohanr/PycharmProjects/Nornir_Auto/venv/lib/python3.9/site-packages/jnpr/junos/utils/start_shell.py", line 81, in wait_for
    if isinstance(data, bytes):
UnboundLocalError: local variable 'data' referenced before assignment

2022-09-23 16:39:53,092 - nornir.core.task -    ERROR -      start() - Host 'mx960-1': task 'pyez_cmd' failed with traceback:
Traceback (most recent call last):
  File "/Users/sohanr/PycharmProjects/Nornir_Auto/venv/lib/python3.9/site-packages/nornir/core/task.py", line 99, in start
    r = self.task(self, **self.params)
  File "/Users/sohanr/PycharmProjects/Nornir_Auto/venv/lib/python3.9/site-packages/nornir_pyez/plugins/tasks/pyez_cmd.py", line 10, in pyez_cmd
    with StartShell(device) as sh:
  File "/Users/sohanr/PycharmProjects/Nornir_Auto/venv/lib/python3.9/site-packages/jnpr/junos/utils/start_shell.py", line 202, in __enter__
    self.open()
  File "/Users/sohanr/PycharmProjects/Nornir_Auto/venv/lib/python3.9/site-packages/jnpr/junos/utils/start_shell.py", line 128, in open
    self.wait_for(_SHELL_PROMPT)
  File "/Users/sohanr/PycharmProjects/Nornir_Auto/venv/lib/python3.9/site-packages/jnpr/junos/utils/start_shell.py", line 81, in wait_for
    if isinstance(data, bytes):
UnboundLocalError: local variable 'data' referenced before assignment

2022-09-23 16:45:59,973 -  nornir.core -     INFO -        run() - Running task 'pyez_cmd' with args {'command': 'show chassis alarms | display xml'} on 3 hosts
2022-09-23 16:46:07,173 - nornir.core.task -    ERROR -      start() - Host 'mx960-2': task 'pyez_cmd' failed with traceback:
Traceback (most recent call last):
  File "/Users/sohanr/PycharmProjects/Nornir_Auto/venv/lib/python3.9/site-packages/nornir/core/task.py", line 99, in start
    r = self.task(self, **self.params)
  File "/Users/sohanr/PycharmProjects/Nornir_Auto/venv/lib/python3.9/site-packages/nornir_pyez/plugins/tasks/pyez_cmd.py", line 10, in pyez_cmd
    with StartShell(device) as sh:
  File "/Users/sohanr/PycharmProjects/Nornir_Auto/venv/lib/python3.9/site-packages/jnpr/junos/utils/start_shell.py", line 202, in __enter__
    self.open()
  File "/Users/sohanr/PycharmProjects/Nornir_Auto/venv/lib/python3.9/site-packages/jnpr/junos/utils/start_shell.py", line 128, in open
    self.wait_for(_SHELL_PROMPT)
  File "/Users/sohanr/PycharmProjects/Nornir_Auto/venv/lib/python3.9/site-packages/jnpr/junos/utils/start_shell.py", line 81, in wait_for
    if isinstance(data, bytes):
UnboundLocalError: local variable 'data' referenced before assignment

2022-09-23 16:46:07,173 - nornir.core.task -    ERROR -      start() - Host 'mx480-3': task 'pyez_cmd' failed with traceback:
Traceback (most recent call last):
  File "/Users/sohanr/PycharmProjects/Nornir_Auto/venv/lib/python3.9/site-packages/nornir/core/task.py", line 99, in start
    r = self.task(self, **self.params)
  File "/Users/sohanr/PycharmProjects/Nornir_Auto/venv/lib/python3.9/site-packages/nornir_pyez/plugins/tasks/pyez_cmd.py", line 10, in pyez_cmd
    with StartShell(device) as sh:
  File "/Users/sohanr/PycharmProjects/Nornir_Auto/venv/lib/python3.9/site-packages/jnpr/junos/utils/start_shell.py", line 202, in __enter__
    self.open()
  File "/Users/sohanr/PycharmProjects/Nornir_Auto/venv/lib/python3.9/site-packages/jnpr/junos/utils/start_shell.py", line 128, in open
    self.wait_for(_SHELL_PROMPT)
  File "/Users/sohanr/PycharmProjects/Nornir_Auto/venv/lib/python3.9/site-packages/jnpr/junos/utils/start_shell.py", line 81, in wait_for
    if isinstance(data, bytes):
UnboundLocalError: local variable 'data' referenced before assignment

2022-09-23 16:46:07,192 - nornir.core.task -    ERROR -      start() - Host 'mx960-1': task 'pyez_cmd' failed with traceback:
Traceback (most recent call last):
  File "/Users/sohanr/PycharmProjects/Nornir_Auto/venv/lib/python3.9/site-packages/nornir/core/task.py", line 99, in start
    r = self.task(self, **self.params)
  File "/Users/sohanr/PycharmProjects/Nornir_Auto/venv/lib/python3.9/site-packages/nornir_pyez/plugins/tasks/pyez_cmd.py", line 10, in pyez_cmd
    with StartShell(device) as sh:
  File "/Users/sohanr/PycharmProjects/Nornir_Auto/venv/lib/python3.9/site-packages/jnpr/junos/utils/start_shell.py", line 202, in __enter__
    self.open()
  File "/Users/sohanr/PycharmProjects/Nornir_Auto/venv/lib/python3.9/site-packages/jnpr/junos/utils/start_shell.py", line 128, in open
    self.wait_for(_SHELL_PROMPT)
  File "/Users/sohanr/PycharmProjects/Nornir_Auto/venv/lib/python3.9/site-packages/jnpr/junos/utils/start_shell.py", line 81, in wait_for
    if isinstance(data, bytes):
UnboundLocalError: local variable 'data' referenced before assignment

2022-09-23 16:46:07,192 -  nornir.core -     INFO -        run() - Running task 'All tasks' with args {} on 3 hosts
2022-09-23 16:49:59,786 -  nornir.core -     INFO -        run() - Running task 'pyez_cmd' with args {'command': 'show chassis alarms | display xml'} on 3 hosts
2022-09-23 16:50:06,784 - nornir.core.task -    ERROR -      start() - Host 'mx960-2': task 'pyez_cmd' failed with traceback:
Traceback (most recent call last):
  File "/Users/sohanr/PycharmProjects/Nornir_Auto/venv/lib/python3.9/site-packages/nornir/core/task.py", line 99, in start
    r = self.task(self, **self.params)
  File "/Users/sohanr/PycharmProjects/Nornir_Auto/venv/lib/python3.9/site-packages/nornir_pyez/plugins/tasks/pyez_cmd.py", line 10, in pyez_cmd
    with StartShell(device) as sh:
  File "/Users/sohanr/PycharmProjects/Nornir_Auto/venv/lib/python3.9/site-packages/jnpr/junos/utils/start_shell.py", line 202, in __enter__
    self.open()
  File "/Users/sohanr/PycharmProjects/Nornir_Auto/venv/lib/python3.9/site-packages/jnpr/junos/utils/start_shell.py", line 128, in open
    self.wait_for(_SHELL_PROMPT)
  File "/Users/sohanr/PycharmProjects/Nornir_Auto/venv/lib/python3.9/site-packages/jnpr/junos/utils/start_shell.py", line 81, in wait_for
    if isinstance(data, bytes):
UnboundLocalError: local variable 'data' referenced before assignment

2022-09-23 16:50:06,785 - nornir.core.task -    ERROR -      start() - Host 'mx480-3': task 'pyez_cmd' failed with traceback:
Traceback (most recent call last):
  File "/Users/sohanr/PycharmProjects/Nornir_Auto/venv/lib/python3.9/site-packages/nornir/core/task.py", line 99, in start
    r = self.task(self, **self.params)
  File "/Users/sohanr/PycharmProjects/Nornir_Auto/venv/lib/python3.9/site-packages/nornir_pyez/plugins/tasks/pyez_cmd.py", line 10, in pyez_cmd
    with StartShell(device) as sh:
  File "/Users/sohanr/PycharmProjects/Nornir_Auto/venv/lib/python3.9/site-packages/jnpr/junos/utils/start_shell.py", line 202, in __enter__
    self.open()
  File "/Users/sohanr/PycharmProjects/Nornir_Auto/venv/lib/python3.9/site-packages/jnpr/junos/utils/start_shell.py", line 128, in open
    self.wait_for(_SHELL_PROMPT)
  File "/Users/sohanr/PycharmProjects/Nornir_Auto/venv/lib/python3.9/site-packages/jnpr/junos/utils/start_shell.py", line 81, in wait_for
    if isinstance(data, bytes):
UnboundLocalError: local variable 'data' referenced before assignment

2022-09-23 16:50:06,823 - nornir.core.task -    ERROR -      start() - Host 'mx960-1': task 'pyez_cmd' failed with traceback:
Traceback (most recent call last):
  File "/Users/sohanr/PycharmProjects/Nornir_Auto/venv/lib/python3.9/site-packages/nornir/core/task.py", line 99, in start
    r = self.task(self, **self.params)
  File "/Users/sohanr/PycharmProjects/Nornir_Auto/venv/lib/python3.9/site-packages/nornir_pyez/plugins/tasks/pyez_cmd.py", line 10, in pyez_cmd
    with StartShell(device) as sh:
  File "/Users/sohanr/PycharmProjects/Nornir_Auto/venv/lib/python3.9/site-packages/jnpr/junos/utils/start_shell.py", line 202, in __enter__
    self.open()
  File "/Users/sohanr/PycharmProjects/Nornir_Auto/venv/lib/python3.9/site-packages/jnpr/junos/utils/start_shell.py", line 128, in open
    self.wait_for(_SHELL_PROMPT)
  File "/Users/sohanr/PycharmProjects/Nornir_Auto/venv/lib/python3.9/site-packages/jnpr/junos/utils/start_shell.py", line 81, in wait_for
    if isinstance(data, bytes):
UnboundLocalError: local variable 'data' referenced before assignment

2022-09-23 16:50:06,823 -  nornir.core -     INFO -        run() - Running task 'All tasks' with args {} on 3 hosts
2022-09-23 16:50:33,456 -  nornir.core -     INFO -        run() - Running task 'pyez_cmd' with args {'command': 'show chassis alarms | display xml'} on 3 hosts
2022-09-23 16:50:40,394 - nornir.core.task -    ERROR -      start() - Host 'mx480-3': task 'pyez_cmd' failed with traceback:
Traceback (most recent call last):
  File "/Users/sohanr/PycharmProjects/Nornir_Auto/venv/lib/python3.9/site-packages/nornir/core/task.py", line 99, in start
    r = self.task(self, **self.params)
  File "/Users/sohanr/PycharmProjects/Nornir_Auto/venv/lib/python3.9/site-packages/nornir_pyez/plugins/tasks/pyez_cmd.py", line 10, in pyez_cmd
    with StartShell(device) as sh:
  File "/Users/sohanr/PycharmProjects/Nornir_Auto/venv/lib/python3.9/site-packages/jnpr/junos/utils/start_shell.py", line 202, in __enter__
    self.open()
  File "/Users/sohanr/PycharmProjects/Nornir_Auto/venv/lib/python3.9/site-packages/jnpr/junos/utils/start_shell.py", line 128, in open
    self.wait_for(_SHELL_PROMPT)
  File "/Users/sohanr/PycharmProjects/Nornir_Auto/venv/lib/python3.9/site-packages/jnpr/junos/utils/start_shell.py", line 81, in wait_for
    if isinstance(data, bytes):
UnboundLocalError: local variable 'data' referenced before assignment

2022-09-23 16:50:40,395 - nornir.core.task -    ERROR -      start() - Host 'mx960-2': task 'pyez_cmd' failed with traceback:
Traceback (most recent call last):
  File "/Users/sohanr/PycharmProjects/Nornir_Auto/venv/lib/python3.9/site-packages/nornir/core/task.py", line 99, in start
    r = self.task(self, **self.params)
  File "/Users/sohanr/PycharmProjects/Nornir_Auto/venv/lib/python3.9/site-packages/nornir_pyez/plugins/tasks/pyez_cmd.py", line 10, in pyez_cmd
    with StartShell(device) as sh:
  File "/Users/sohanr/PycharmProjects/Nornir_Auto/venv/lib/python3.9/site-packages/jnpr/junos/utils/start_shell.py", line 202, in __enter__
    self.open()
  File "/Users/sohanr/PycharmProjects/Nornir_Auto/venv/lib/python3.9/site-packages/jnpr/junos/utils/start_shell.py", line 128, in open
    self.wait_for(_SHELL_PROMPT)
  File "/Users/sohanr/PycharmProjects/Nornir_Auto/venv/lib/python3.9/site-packages/jnpr/junos/utils/start_shell.py", line 81, in wait_for
    if isinstance(data, bytes):
UnboundLocalError: local variable 'data' referenced before assignment

2022-09-23 16:50:40,581 - nornir.core.task -    ERROR -      start() - Host 'mx960-1': task 'pyez_cmd' failed with traceback:
Traceback (most recent call last):
  File "/Users/sohanr/PycharmProjects/Nornir_Auto/venv/lib/python3.9/site-packages/nornir/core/task.py", line 99, in start
    r = self.task(self, **self.params)
  File "/Users/sohanr/PycharmProjects/Nornir_Auto/venv/lib/python3.9/site-packages/nornir_pyez/plugins/tasks/pyez_cmd.py", line 10, in pyez_cmd
    with StartShell(device) as sh:
  File "/Users/sohanr/PycharmProjects/Nornir_Auto/venv/lib/python3.9/site-packages/jnpr/junos/utils/start_shell.py", line 202, in __enter__
    self.open()
  File "/Users/sohanr/PycharmProjects/Nornir_Auto/venv/lib/python3.9/site-packages/jnpr/junos/utils/start_shell.py", line 128, in open
    self.wait_for(_SHELL_PROMPT)
  File "/Users/sohanr/PycharmProjects/Nornir_Auto/venv/lib/python3.9/site-packages/jnpr/junos/utils/start_shell.py", line 81, in wait_for
    if isinstance(data, bytes):
UnboundLocalError: local variable 'data' referenced before assignment

2022-09-23 16:50:40,582 -  nornir.core -     INFO -        run() - Running task 'All tasks' with args {} on 3 hosts
2022-09-23 16:53:32,795 -  nornir.core -     INFO -        run() - Running task 'pyez_cmd' with args {'command': 'show chassis alarms | display xml'} on 3 hosts
2022-09-23 16:53:39,554 - nornir.core.task -    ERROR -      start() - Host 'mx480-3': task 'pyez_cmd' failed with traceback:
Traceback (most recent call last):
  File "/Users/sohanr/PycharmProjects/Nornir_Auto/venv/lib/python3.9/site-packages/nornir/core/task.py", line 99, in start
    r = self.task(self, **self.params)
  File "/Users/sohanr/PycharmProjects/Nornir_Auto/venv/lib/python3.9/site-packages/nornir_pyez/plugins/tasks/pyez_cmd.py", line 10, in pyez_cmd
    with StartShell(device) as sh:
  File "/Users/sohanr/PycharmProjects/Nornir_Auto/venv/lib/python3.9/site-packages/jnpr/junos/utils/start_shell.py", line 202, in __enter__
    self.open()
  File "/Users/sohanr/PycharmProjects/Nornir_Auto/venv/lib/python3.9/site-packages/jnpr/junos/utils/start_shell.py", line 128, in open
    self.wait_for(_SHELL_PROMPT)
  File "/Users/sohanr/PycharmProjects/Nornir_Auto/venv/lib/python3.9/site-packages/jnpr/junos/utils/start_shell.py", line 81, in wait_for
    if isinstance(data, bytes):
UnboundLocalError: local variable 'data' referenced before assignment

2022-09-23 16:53:39,554 - nornir.core.task -    ERROR -      start() - Host 'mx960-2': task 'pyez_cmd' failed with traceback:
Traceback (most recent call last):
  File "/Users/sohanr/PycharmProjects/Nornir_Auto/venv/lib/python3.9/site-packages/nornir/core/task.py", line 99, in start
    r = self.task(self, **self.params)
  File "/Users/sohanr/PycharmProjects/Nornir_Auto/venv/lib/python3.9/site-packages/nornir_pyez/plugins/tasks/pyez_cmd.py", line 10, in pyez_cmd
    with StartShell(device) as sh:
  File "/Users/sohanr/PycharmProjects/Nornir_Auto/venv/lib/python3.9/site-packages/jnpr/junos/utils/start_shell.py", line 202, in __enter__
    self.open()
  File "/Users/sohanr/PycharmProjects/Nornir_Auto/venv/lib/python3.9/site-packages/jnpr/junos/utils/start_shell.py", line 128, in open
    self.wait_for(_SHELL_PROMPT)
  File "/Users/sohanr/PycharmProjects/Nornir_Auto/venv/lib/python3.9/site-packages/jnpr/junos/utils/start_shell.py", line 81, in wait_for
    if isinstance(data, bytes):
UnboundLocalError: local variable 'data' referenced before assignment

2022-09-23 16:53:39,905 - nornir.core.task -    ERROR -      start() - Host 'mx960-1': task 'pyez_cmd' failed with traceback:
Traceback (most recent call last):
  File "/Users/sohanr/PycharmProjects/Nornir_Auto/venv/lib/python3.9/site-packages/nornir/core/task.py", line 99, in start
    r = self.task(self, **self.params)
  File "/Users/sohanr/PycharmProjects/Nornir_Auto/venv/lib/python3.9/site-packages/nornir_pyez/plugins/tasks/pyez_cmd.py", line 10, in pyez_cmd
    with StartShell(device) as sh:
  File "/Users/sohanr/PycharmProjects/Nornir_Auto/venv/lib/python3.9/site-packages/jnpr/junos/utils/start_shell.py", line 202, in __enter__
    self.open()
  File "/Users/sohanr/PycharmProjects/Nornir_Auto/venv/lib/python3.9/site-packages/jnpr/junos/utils/start_shell.py", line 128, in open
    self.wait_for(_SHELL_PROMPT)
  File "/Users/sohanr/PycharmProjects/Nornir_Auto/venv/lib/python3.9/site-packages/jnpr/junos/utils/start_shell.py", line 81, in wait_for
    if isinstance(data, bytes):
UnboundLocalError: local variable 'data' referenced before assignment

2022-09-23 16:53:39,906 -  nornir.core -     INFO -        run() - Running task 'All tasks' with args {} on 3 hosts
2022-09-23 16:54:05,688 -  nornir.core -     INFO -        run() - Running task 'All tasks' with args {} on 3 hosts
2022-09-23 16:59:03,604 -  nornir.core -     INFO -        run() - Running task 'tasks_group' with args {} on 3 hosts
2022-09-23 17:00:01,191 -  nornir.core -     INFO -        run() - Running task 'tasks_group' with args {} on 3 hosts
2022-09-23 17:01:00,528 -  nornir.core -     INFO -        run() - Running task 'tasks_group' with args {} on 3 hosts
2022-09-23 17:13:02,013 -  nornir.core -     INFO -        run() - Running task 'pyez_rpc' with args {'func': 'get-system-alarm-information'} on 3 hosts
2022-09-23 17:33:43,333 -  nornir.core -     INFO -        run() - Running task 'pyez_facts' with args {} on 3 hosts
2022-09-23 17:33:46,806 -  nornir.core -     INFO -        run() - Running task 'main_task' with args {} on 3 hosts
2022-09-23 17:41:08,761 -  nornir.core -     INFO -        run() - Running task 'pyez_facts' with args {} on 3 hosts
2022-09-23 17:41:12,143 -  nornir.core -     INFO -        run() - Running task 'main_task' with args {} on 3 hosts
2022-09-23 17:42:08,555 -  nornir.core -     INFO -        run() - Running task 'pyez_facts' with args {} on 3 hosts
2022-09-23 17:42:12,051 -  nornir.core -     INFO -        run() - Running task 'main_task' with args {} on 3 hosts
2022-09-23 17:45:42,121 -  nornir.core -     INFO -        run() - Running task 'pyez_facts' with args {} on 3 hosts
2022-09-23 17:45:45,676 -  nornir.core -     INFO -        run() - Running task 'main_task' with args {} on 3 hosts
2022-09-23 17:47:37,199 -  nornir.core -     INFO -        run() - Running task 'pyez_facts' with args {} on 3 hosts
2022-09-23 17:47:40,637 -  nornir.core -     INFO -        run() - Running task 'main_task' with args {} on 3 hosts
2022-09-23 17:48:45,748 -  nornir.core -     INFO -        run() - Running task 'pyez_facts' with args {} on 3 hosts
2022-09-23 17:48:49,245 -  nornir.core -     INFO -        run() - Running task 'main_task' with args {} on 3 hosts
2022-09-23 17:50:26,478 -  nornir.core -     INFO -        run() - Running task 'pyez_facts' with args {} on 3 hosts
2022-09-23 17:50:30,010 -  nornir.core -     INFO -        run() - Running task 'main_task' with args {} on 3 hosts
2022-09-23 17:53:27,880 -  nornir.core -     INFO -        run() - Running task 'pyez_facts' with args {} on 3 hosts
2022-09-23 17:53:31,354 -  nornir.core -     INFO -        run() - Running task 'main_task' with args {} on 3 hosts
2022-09-23 18:04:05,185 -  nornir.core -     INFO -        run() - Running task 'pyez_facts' with args {} on 3 hosts
2022-09-23 18:04:08,730 -  nornir.core -     INFO -        run() - Running task 'main_task' with args {} on 3 hosts
2022-09-23 18:05:42,645 -  nornir.core -     INFO -        run() - Running task 'pyez_facts' with args {} on 3 hosts
2022-09-23 18:05:46,026 -  nornir.core -     INFO -        run() - Running task 'main_task' with args {} on 3 hosts
2022-09-23 18:47:16,755 -  nornir.core -     INFO -        run() - Running task 'pyez_facts' with args {} on 3 hosts
2022-09-23 18:47:20,316 -  nornir.core -     INFO -        run() - Running task 'main_task' with args {} on 3 hosts
2022-09-23 19:15:41,788 -  nornir.core -     INFO -        run() - Running task 'pyez_facts' with args {} on 3 hosts
2022-09-23 19:15:45,302 -  nornir.core -     INFO -        run() - Running task 'main_task' with args {} on 3 hosts
2022-09-23 19:16:43,251 -  nornir.core -     INFO -        run() - Running task 'pyez_facts' with args {} on 3 hosts
2022-09-23 19:16:48,846 -  nornir.core -     INFO -        run() - Running task 'main_task' with args {} on 3 hosts
2022-09-23 19:17:57,661 -  nornir.core -     INFO -        run() - Running task 'pyez_facts' with args {} on 3 hosts
2022-09-23 19:18:01,812 -  nornir.core -     INFO -        run() - Running task 'main_task' with args {} on 3 hosts
2022-09-23 19:18:38,032 -  nornir.core -     INFO -        run() - Running task 'pyez_facts' with args {} on 3 hosts
2022-09-23 19:18:43,989 -  nornir.core -     INFO -        run() - Running task 'main_task' with args {} on 3 hosts
2022-09-23 19:19:42,703 -  nornir.core -     INFO -        run() - Running task 'pyez_facts' with args {} on 3 hosts
2022-09-23 19:19:46,227 -  nornir.core -     INFO -        run() - Running task 'main_task' with args {} on 3 hosts
2022-09-23 19:22:40,437 -  nornir.core -     INFO -        run() - Running task 'pyez_facts' with args {} on 3 hosts
2022-09-23 19:22:43,999 -  nornir.core -     INFO -        run() - Running task 'main_task' with args {} on 3 hosts
2022-09-23 19:23:26,170 -  nornir.core -     INFO -        run() - Running task 'pyez_facts' with args {} on 3 hosts
2022-09-23 19:23:29,654 -  nornir.core -     INFO -        run() - Running task 'main_task' with args {} on 3 hosts
2022-09-23 19:34:24,564 -  nornir.core -     INFO -        run() - Running task 'pyez_rpc' with args {'func': 'get-bgp-summary-information'} on 3 hosts
2022-09-23 19:38:02,670 -  nornir.core -     INFO -        run() - Running task 'pyez_rpc' with args {'func': 'get-isis-adjacency-information'} on 3 hosts
2022-09-23 19:46:02,438 -  nornir.core -     INFO -        run() - Running task 'pyez_rpc' with args {'func': 'get-isis-adjacency-information'} on 3 hosts
2022-09-23 19:47:16,707 -  nornir.core -     INFO -        run() - Running task 'pyez_rpc' with args {'func': 'get-bgp-summary-information'} on 3 hosts
2022-09-23 19:56:12,638 -  nornir.core -     INFO -        run() - Running task 'pyez_facts' with args {} on 3 hosts
2022-09-23 19:56:16,164 -  nornir.core -     INFO -        run() - Running task 'main_task' with args {} on 3 hosts
2022-09-23 19:57:14,564 -  nornir.core -     INFO -        run() - Running task 'pyez_facts' with args {} on 3 hosts
2022-09-23 19:57:18,130 -  nornir.core -     INFO -        run() - Running task 'main_task' with args {} on 3 hosts
2022-09-23 21:04:36,569 -  nornir.core -     INFO -        run() - Running task 'pyez_facts' with args {} on 3 hosts
2022-09-23 21:04:40,191 -  nornir.core -     INFO -        run() - Running task 'main_task' with args {} on 3 hosts
2022-09-23 21:05:30,933 -  nornir.core -     INFO -        run() - Running task 'pyez_facts' with args {} on 3 hosts
2022-09-23 21:05:34,472 -  nornir.core -     INFO -        run() - Running task 'main_task' with args {} on 3 hosts
2022-09-23 21:16:30,543 -  nornir.core -     INFO -        run() - Running task 'pyez_facts' with args {} on 3 hosts
2022-09-23 21:16:34,028 -  nornir.core -     INFO -        run() - Running task 'main_task' with args {} on 3 hosts
2022-09-23 23:03:15,169 -  nornir.core -     INFO -        run() - Running task 'pyez_facts' with args {} on 3 hosts
2022-09-23 23:03:18,705 -  nornir.core -     INFO -        run() - Running task 'main_task' with args {} on 3 hosts
2022-09-23 23:10:31,069 -  nornir.core -     INFO -        run() - Running task 'pyez_facts' with args {} on 3 hosts
2022-09-23 23:10:39,957 -  nornir.core -     INFO -        run() - Running task 'main_task' with args {} on 3 hosts
2022-09-23 23:12:20,459 -  nornir.core -     INFO -        run() - Running task 'pyez_facts' with args {} on 3 hosts
2022-09-23 23:12:23,993 -  nornir.core -     INFO -        run() - Running task 'main_task' with args {} on 3 hosts
2022-09-23 23:13:15,678 -  nornir.core -     INFO -        run() - Running task 'pyez_facts' with args {} on 3 hosts
2022-09-23 23:13:19,201 -  nornir.core -     INFO -        run() - Running task 'main_task' with args {} on 3 hosts
2022-09-23 23:15:23,985 -  nornir.core -     INFO -        run() - Running task 'pyez_facts' with args {} on 3 hosts
2022-09-23 23:15:27,406 -  nornir.core -     INFO -        run() - Running task 'main_task' with args {} on 3 hosts
2022-09-23 23:16:32,582 -  nornir.core -     INFO -        run() - Running task 'pyez_facts' with args {} on 3 hosts
2022-09-23 23:16:36,124 -  nornir.core -     INFO -        run() - Running task 'main_task' with args {} on 3 hosts
2022-09-23 23:17:42,108 -  nornir.core -     INFO -        run() - Running task 'pyez_facts' with args {} on 3 hosts
2022-09-23 23:17:45,641 -  nornir.core -     INFO -        run() - Running task 'main_task' with args {} on 3 hosts
2022-09-23 23:19:09,143 -  nornir.core -     INFO -        run() - Running task 'pyez_facts' with args {} on 3 hosts
2022-09-23 23:19:12,598 -  nornir.core -     INFO -        run() - Running task 'main_task' with args {} on 3 hosts
2022-09-23 23:21:30,098 -  nornir.core -     INFO -        run() - Running task 'pyez_facts' with args {} on 3 hosts
2022-09-23 23:21:33,584 -  nornir.core -     INFO -        run() - Running task 'main_task' with args {} on 3 hosts
2022-09-23 23:22:17,649 -  nornir.core -     INFO -        run() - Running task 'pyez_facts' with args {} on 3 hosts
2022-09-23 23:22:21,204 -  nornir.core -     INFO -        run() - Running task 'main_task' with args {} on 3 hosts
2022-09-23 23:23:24,893 -  nornir.core -     INFO -        run() - Running task 'pyez_facts' with args {} on 3 hosts
2022-09-23 23:23:28,274 -  nornir.core -     INFO -        run() - Running task 'main_task' with args {} on 3 hosts
2022-09-23 23:25:22,272 -  nornir.core -     INFO -        run() - Running task 'pyez_facts' with args {} on 3 hosts
2022-09-23 23:25:25,845 -  nornir.core -     INFO -        run() - Running task 'main_task' with args {} on 3 hosts
2022-09-23 23:28:34,496 -  nornir.core -     INFO -        run() - Running task 'pyez_facts' with args {} on 3 hosts
2022-09-23 23:28:38,048 -  nornir.core -     INFO -        run() - Running task 'main_task' with args {} on 3 hosts
2022-09-23 23:29:27,734 -  nornir.core -     INFO -        run() - Running task 'pyez_facts' with args {} on 3 hosts
2022-09-23 23:29:31,303 -  nornir.core -     INFO -        run() - Running task 'main_task' with args {} on 3 hosts
2022-09-23 23:31:26,506 -  nornir.core -     INFO -        run() - Running task 'pyez_facts' with args {} on 3 hosts
2022-09-23 23:31:29,826 -  nornir.core -     INFO -        run() - Running task 'main_task' with args {} on 3 hosts
2022-09-23 23:35:13,257 -  nornir.core -     INFO -        run() - Running task 'pyez_facts' with args {} on 3 hosts
2022-09-23 23:35:16,807 -  nornir.core -     INFO -        run() - Running task 'main_task' with args {} on 3 hosts
2022-09-23 23:36:14,609 -  nornir.core -     INFO -        run() - Running task 'pyez_facts' with args {} on 3 hosts
2022-09-23 23:36:18,131 -  nornir.core -     INFO -        run() - Running task 'main_task' with args {} on 3 hosts
2022-09-23 23:40:23,146 -  nornir.core -     INFO -        run() - Running task 'pyez_facts' with args {} on 3 hosts
2022-09-23 23:40:26,661 -  nornir.core -     INFO -        run() - Running task 'main_task' with args {} on 3 hosts
2022-09-23 23:47:55,634 -  nornir.core -     INFO -        run() - Running task 'pyez_facts' with args {} on 3 hosts
2022-09-23 23:47:59,165 -  nornir.core -     INFO -        run() - Running task 'main_task' with args {} on 3 hosts
2022-09-23 23:49:37,104 -  nornir.core -     INFO -        run() - Running task 'pyez_facts' with args {} on 3 hosts
2022-09-23 23:49:45,173 -  nornir.core -     INFO -        run() - Running task 'main_task' with args {} on 3 hosts
2022-09-23 23:50:58,999 -  nornir.core -     INFO -        run() - Running task 'pyez_facts' with args {} on 3 hosts
2022-09-23 23:51:04,232 -  nornir.core -     INFO -        run() - Running task 'main_task' with args {} on 3 hosts
2022-09-23 23:52:45,908 -  nornir.core -     INFO -        run() - Running task 'pyez_facts' with args {} on 3 hosts
2022-09-23 23:52:49,487 -  nornir.core -     INFO -        run() - Running task 'main_task' with args {} on 3 hosts
2022-09-23 23:56:03,782 -  nornir.core -     INFO -        run() - Running task 'pyez_facts' with args {} on 3 hosts
2022-09-23 23:56:07,308 -  nornir.core -     INFO -        run() - Running task 'main_task' with args {} on 3 hosts
2022-09-23 23:57:48,835 -  nornir.core -     INFO -        run() - Running task 'pyez_facts' with args {} on 3 hosts
2022-09-23 23:57:54,342 -  nornir.core -     INFO -        run() - Running task 'main_task' with args {} on 3 hosts
2022-09-23 23:59:16,813 -  nornir.core -     INFO -        run() - Running task 'pyez_facts' with args {} on 3 hosts
2022-09-23 23:59:22,013 -  nornir.core -     INFO -        run() - Running task 'main_task' with args {} on 3 hosts
2022-09-26 10:14:23,752 -  nornir.core -     INFO -        run() - Running task 'pyez_facts' with args {} on 3 hosts
2022-09-26 10:14:27,245 -  nornir.core -     INFO -        run() - Running task 'main_task' with args {} on 3 hosts
2022-09-26 10:15:51,415 -  nornir.core -     INFO -        run() - Running task 'pyez_facts' with args {} on 3 hosts
2022-09-26 10:15:54,902 -  nornir.core -     INFO -        run() - Running task 'main_task' with args {} on 3 hosts
2022-09-26 10:30:38,826 -  nornir.core -     INFO -        run() - Running task 'pyez_facts' with args {} on 3 hosts
2022-09-26 10:30:42,298 -  nornir.core -     INFO -        run() - Running task 'main_task' with args {} on 3 hosts
2022-09-26 10:36:03,665 -  nornir.core -     INFO -        run() - Running task 'pyez_facts' with args {} on 3 hosts
2022-09-26 10:36:07,212 -  nornir.core -     INFO -        run() - Running task 'main_task' with args {} on 3 hosts
2022-09-26 10:38:56,040 -  nornir.core -     INFO -        run() - Running task 'pyez_facts' with args {} on 3 hosts
2022-09-26 10:38:59,544 -  nornir.core -     INFO -        run() - Running task 'main_task' with args {} on 3 hosts
2022-09-26 11:39:19,396 -  nornir.core -     INFO -        run() - Running task 'pyez_facts' with args {} on 3 hosts
2022-09-26 11:39:22,906 -  nornir.core -     INFO -        run() - Running task 'main_task' with args {} on 3 hosts
2022-09-26 11:43:51,714 -  nornir.core -     INFO -        run() - Running task 'pyez_facts' with args {} on 3 hosts
2022-09-26 11:43:55,193 -  nornir.core -     INFO -        run() - Running task 'main_task' with args {} on 3 hosts
2022-09-26 12:14:08,659 -  nornir.core -     INFO -        run() - Running task 'pyez_facts' with args {} on 3 hosts
2022-09-26 12:14:18,801 -  nornir.core -     INFO -        run() - Running task 'main_task' with args {} on 3 hosts
2022-09-26 15:01:47,309 -  nornir.core -     INFO -        run() - Running task 'pyez_facts' with args {} on 3 hosts
2022-09-26 15:01:50,621 -  nornir.core -     INFO -        run() - Running task 'main_task' with args {} on 3 hosts
2022-09-26 15:05:46,542 -  nornir.core -     INFO -        run() - Running task 'pyez_facts' with args {} on 3 hosts
2022-09-26 15:05:49,949 -  nornir.core -     INFO -        run() - Running task 'main_task' with args {} on 3 hosts
2022-09-26 15:06:43,857 -  nornir.core -     INFO -        run() - Running task 'pyez_facts' with args {} on 3 hosts
2022-09-26 15:06:47,207 -  nornir.core -     INFO -        run() - Running task 'main_task' with args {} on 3 hosts
2022-09-27 15:51:53,378 -  nornir.core -     INFO -        run() - Running task 'pyez_rpc' with args {'func': 'get-commit-information'} on 3 hosts
2022-09-27 15:54:42,078 - nornir.core.task -    ERROR -      start() - Host 'mx960-1': task 'pyez_rpc' failed with traceback:
Traceback (most recent call last):
  File "/Users/sohanr/PycharmProjects/Nornir_Auto/venv/lib/python3.9/site-packages/jnpr/junos/device.py", line 834, in execute
    rpc_rsp_e = self._rpc_reply(
  File "/Users/sohanr/PycharmProjects/Nornir_Auto/venv/lib/python3.9/site-packages/jnpr/junos/decorators.py", line 117, in wrapper
    rsp = function(self, *args, **kwargs)
  File "/Users/sohanr/PycharmProjects/Nornir_Auto/venv/lib/python3.9/site-packages/jnpr/junos/device.py", line 1457, in _rpc_reply
    return self._conn.rpc(rpc_cmd_e, filter_xml)._NCElement__doc
  File "/Users/sohanr/PycharmProjects/Nornir_Auto/venv/lib/python3.9/site-packages/ncclient/manager.py", line 246, in execute
    return cls(self._session,
  File "/Users/sohanr/PycharmProjects/Nornir_Auto/venv/lib/python3.9/site-packages/ncclient/operations/third_party/juniper/rpc.py", line 52, in request
    return self._request(rpc)
  File "/Users/sohanr/PycharmProjects/Nornir_Auto/venv/lib/python3.9/site-packages/ncclient/operations/rpc.py", line 364, in _request
    raise self._error
  File "/Users/sohanr/PycharmProjects/Nornir_Auto/venv/lib/python3.9/site-packages/ncclient/transport/ssh.py", line 514, in run
    raise SessionCloseError(self._buffer.getvalue())
ncclient.transport.errors.SessionCloseError: Unexpected session close

During handling of the above exception, another exception occurred:

Traceback (most recent call last):
  File "/Users/sohanr/PycharmProjects/Nornir_Auto/venv/lib/python3.9/site-packages/nornir/core/task.py", line 99, in start
    r = self.task(self, **self.params)
  File "/Users/sohanr/PycharmProjects/Nornir_Auto/venv/lib/python3.9/site-packages/nornir_pyez/plugins/tasks/pyez_rpc.py", line 21, in pyez_rpc
    data = function()
  File "/Users/sohanr/PycharmProjects/Nornir_Auto/venv/lib/python3.9/site-packages/jnpr/junos/rpcmeta.py", line 364, in _exec_rpc
    return self._junos.execute(rpc, **dec_args)
  File "/Users/sohanr/PycharmProjects/Nornir_Auto/venv/lib/python3.9/site-packages/jnpr/junos/decorators.py", line 76, in wrapper
    return function(*args, **kwargs)
  File "/Users/sohanr/PycharmProjects/Nornir_Auto/venv/lib/python3.9/site-packages/jnpr/junos/decorators.py", line 31, in wrapper
    return function(*args, **kwargs)
  File "/Users/sohanr/PycharmProjects/Nornir_Auto/venv/lib/python3.9/site-packages/jnpr/junos/device.py", line 844, in execute
    raise EzErrors.ConnectClosedError(self)
jnpr.junos.exception.ConnectClosedError: ConnectClosedError(10.13.111.18)

2022-09-27 15:54:45,132 - nornir.core.task -    ERROR -      start() - Host 'mx960-2': task 'pyez_rpc' failed with traceback:
Traceback (most recent call last):
  File "/Users/sohanr/PycharmProjects/Nornir_Auto/venv/lib/python3.9/site-packages/jnpr/junos/device.py", line 834, in execute
    rpc_rsp_e = self._rpc_reply(
  File "/Users/sohanr/PycharmProjects/Nornir_Auto/venv/lib/python3.9/site-packages/jnpr/junos/decorators.py", line 117, in wrapper
    rsp = function(self, *args, **kwargs)
  File "/Users/sohanr/PycharmProjects/Nornir_Auto/venv/lib/python3.9/site-packages/jnpr/junos/device.py", line 1457, in _rpc_reply
    return self._conn.rpc(rpc_cmd_e, filter_xml)._NCElement__doc
  File "/Users/sohanr/PycharmProjects/Nornir_Auto/venv/lib/python3.9/site-packages/ncclient/manager.py", line 246, in execute
    return cls(self._session,
  File "/Users/sohanr/PycharmProjects/Nornir_Auto/venv/lib/python3.9/site-packages/ncclient/operations/third_party/juniper/rpc.py", line 52, in request
    return self._request(rpc)
  File "/Users/sohanr/PycharmProjects/Nornir_Auto/venv/lib/python3.9/site-packages/ncclient/operations/rpc.py", line 364, in _request
    raise self._error
  File "/Users/sohanr/PycharmProjects/Nornir_Auto/venv/lib/python3.9/site-packages/ncclient/transport/ssh.py", line 514, in run
    raise SessionCloseError(self._buffer.getvalue())
ncclient.transport.errors.SessionCloseError: Unexpected session close

During handling of the above exception, another exception occurred:

Traceback (most recent call last):
  File "/Users/sohanr/PycharmProjects/Nornir_Auto/venv/lib/python3.9/site-packages/nornir/core/task.py", line 99, in start
    r = self.task(self, **self.params)
  File "/Users/sohanr/PycharmProjects/Nornir_Auto/venv/lib/python3.9/site-packages/nornir_pyez/plugins/tasks/pyez_rpc.py", line 21, in pyez_rpc
    data = function()
  File "/Users/sohanr/PycharmProjects/Nornir_Auto/venv/lib/python3.9/site-packages/jnpr/junos/rpcmeta.py", line 364, in _exec_rpc
    return self._junos.execute(rpc, **dec_args)
  File "/Users/sohanr/PycharmProjects/Nornir_Auto/venv/lib/python3.9/site-packages/jnpr/junos/decorators.py", line 76, in wrapper
    return function(*args, **kwargs)
  File "/Users/sohanr/PycharmProjects/Nornir_Auto/venv/lib/python3.9/site-packages/jnpr/junos/decorators.py", line 31, in wrapper
    return function(*args, **kwargs)
  File "/Users/sohanr/PycharmProjects/Nornir_Auto/venv/lib/python3.9/site-packages/jnpr/junos/device.py", line 844, in execute
    raise EzErrors.ConnectClosedError(self)
jnpr.junos.exception.ConnectClosedError: ConnectClosedError(10.13.111.2)

2022-09-27 15:55:05,155 - nornir.core.task -    ERROR -      start() - Host 'mx480-3': task 'pyez_rpc' failed with traceback:
Traceback (most recent call last):
  File "/Users/sohanr/PycharmProjects/Nornir_Auto/venv/lib/python3.9/site-packages/jnpr/junos/device.py", line 834, in execute
    rpc_rsp_e = self._rpc_reply(
  File "/Users/sohanr/PycharmProjects/Nornir_Auto/venv/lib/python3.9/site-packages/jnpr/junos/decorators.py", line 117, in wrapper
    rsp = function(self, *args, **kwargs)
  File "/Users/sohanr/PycharmProjects/Nornir_Auto/venv/lib/python3.9/site-packages/jnpr/junos/device.py", line 1457, in _rpc_reply
    return self._conn.rpc(rpc_cmd_e, filter_xml)._NCElement__doc
  File "/Users/sohanr/PycharmProjects/Nornir_Auto/venv/lib/python3.9/site-packages/ncclient/manager.py", line 246, in execute
    return cls(self._session,
  File "/Users/sohanr/PycharmProjects/Nornir_Auto/venv/lib/python3.9/site-packages/ncclient/operations/third_party/juniper/rpc.py", line 52, in request
    return self._request(rpc)
  File "/Users/sohanr/PycharmProjects/Nornir_Auto/venv/lib/python3.9/site-packages/ncclient/operations/rpc.py", line 364, in _request
    raise self._error
  File "/Users/sohanr/PycharmProjects/Nornir_Auto/venv/lib/python3.9/site-packages/ncclient/transport/ssh.py", line 514, in run
    raise SessionCloseError(self._buffer.getvalue())
ncclient.transport.errors.SessionCloseError: Unexpected session close

During handling of the above exception, another exception occurred:

Traceback (most recent call last):
  File "/Users/sohanr/PycharmProjects/Nornir_Auto/venv/lib/python3.9/site-packages/nornir/core/task.py", line 99, in start
    r = self.task(self, **self.params)
  File "/Users/sohanr/PycharmProjects/Nornir_Auto/venv/lib/python3.9/site-packages/nornir_pyez/plugins/tasks/pyez_rpc.py", line 21, in pyez_rpc
    data = function()
  File "/Users/sohanr/PycharmProjects/Nornir_Auto/venv/lib/python3.9/site-packages/jnpr/junos/rpcmeta.py", line 364, in _exec_rpc
    return self._junos.execute(rpc, **dec_args)
  File "/Users/sohanr/PycharmProjects/Nornir_Auto/venv/lib/python3.9/site-packages/jnpr/junos/decorators.py", line 76, in wrapper
    return function(*args, **kwargs)
  File "/Users/sohanr/PycharmProjects/Nornir_Auto/venv/lib/python3.9/site-packages/jnpr/junos/decorators.py", line 31, in wrapper
    return function(*args, **kwargs)
  File "/Users/sohanr/PycharmProjects/Nornir_Auto/venv/lib/python3.9/site-packages/jnpr/junos/device.py", line 844, in execute
    raise EzErrors.ConnectClosedError(self)
jnpr.junos.exception.ConnectClosedError: ConnectClosedError(10.13.110.60)

2022-09-27 15:57:14,139 -  nornir.core -     INFO -        run() - Running task 'pyez_rpc' with args {'func': 'get-system-core-dumps'} on 3 hosts
2022-09-27 16:15:20,928 -  nornir.core -     INFO -        run() - Running task 'pyez_rpc' with args {'func': 'get-commit-information'} on 3 hosts
2022-09-27 16:24:07,005 -  nornir.core -     INFO -        run() - Running task 'pyez_facts' with args {} on 3 hosts
2022-09-27 16:24:10,496 -  nornir.core -     INFO -        run() - Running task 'main_task' with args {} on 3 hosts
2022-09-27 16:25:41,058 -  nornir.core -     INFO -        run() - Running task 'pyez_facts' with args {} on 3 hosts
2022-09-27 16:25:44,590 -  nornir.core -     INFO -        run() - Running task 'main_task' with args {} on 3 hosts
2022-09-27 16:29:35,131 -  nornir.core -     INFO -        run() - Running task 'pyez_facts' with args {} on 3 hosts
2022-09-27 16:29:38,549 -  nornir.core -     INFO -        run() - Running task 'main_task' with args {} on 3 hosts
2022-09-27 16:33:43,362 -  nornir.core -     INFO -        run() - Running task 'pyez_facts' with args {} on 3 hosts
2022-09-27 16:33:46,900 -  nornir.core -     INFO -        run() - Running task 'main_task' with args {} on 3 hosts
2022-09-27 17:16:24,151 -  nornir.core -     INFO -        run() - Running task 'pyez_facts' with args {} on 3 hosts
2022-09-27 17:16:28,579 -  nornir.core -     INFO -        run() - Running task 'main_task' with args {} on 3 hosts
2022-09-28 17:19:37,190 -  nornir.core -     INFO -        run() - Running task 'pyez_facts' with args {} on 3 hosts
2022-09-28 17:19:38,009 - nornir.core.task -    ERROR -      start() - Host 'mx960-1': task 'pyez_facts' failed with traceback:
Traceback (most recent call last):
  File "/Users/sohanr/PycharmProjects/Nornir_Auto/venv/lib/python3.9/site-packages/paramiko/transport.py", line 2271, in _check_banner
    buf = self.packetizer.readline(timeout)
  File "/Users/sohanr/PycharmProjects/Nornir_Auto/venv/lib/python3.9/site-packages/paramiko/packet.py", line 380, in readline
    buf += self._read_timeout(timeout)
  File "/Users/sohanr/PycharmProjects/Nornir_Auto/venv/lib/python3.9/site-packages/paramiko/packet.py", line 607, in _read_timeout
    x = self.__socket.recv(128)
ConnectionResetError: [Errno 54] Connection reset by peer

During handling of the above exception, another exception occurred:

Traceback (most recent call last):
  File "/Users/sohanr/PycharmProjects/Nornir_Auto/venv/lib/python3.9/site-packages/ncclient/transport/ssh.py", line 331, in connect
    self._transport.start_client()
  File "/Users/sohanr/PycharmProjects/Nornir_Auto/venv/lib/python3.9/site-packages/paramiko/transport.py", line 699, in start_client
    raise e
  File "/Users/sohanr/PycharmProjects/Nornir_Auto/venv/lib/python3.9/site-packages/paramiko/transport.py", line 2094, in run
    self._check_banner()
  File "/Users/sohanr/PycharmProjects/Nornir_Auto/venv/lib/python3.9/site-packages/paramiko/transport.py", line 2275, in _check_banner
    raise SSHException(
paramiko.ssh_exception.SSHException: Error reading SSH protocol banner[Errno 54] Connection reset by peer

During handling of the above exception, another exception occurred:

Traceback (most recent call last):
  File "/Users/sohanr/PycharmProjects/Nornir_Auto/venv/lib/python3.9/site-packages/jnpr/junos/device.py", line 1362, in open
    self._conn = netconf_ssh.connect(
  File "/Users/sohanr/PycharmProjects/Nornir_Auto/venv/lib/python3.9/site-packages/ncclient/manager.py", line 176, in connect
    return connect_ssh(*args, **kwds)
  File "/Users/sohanr/PycharmProjects/Nornir_Auto/venv/lib/python3.9/site-packages/ncclient/manager.py", line 143, in connect_ssh
    session.connect(*args, **kwds)
  File "/Users/sohanr/PycharmProjects/Nornir_Auto/venv/lib/python3.9/site-packages/ncclient/transport/ssh.py", line 333, in connect
    raise SSHError('Negotiation failed: %s' % e)
ncclient.transport.errors.SSHError: Negotiation failed: Error reading SSH protocol banner[Errno 54] Connection reset by peer

During handling of the above exception, another exception occurred:

Traceback (most recent call last):
  File "/Users/sohanr/PycharmProjects/Nornir_Auto/venv/lib/python3.9/site-packages/nornir/core/task.py", line 99, in start
    r = self.task(self, **self.params)
  File "/Users/sohanr/PycharmProjects/Nornir_Auto/venv/lib/python3.9/site-packages/nornir_pyez/plugins/tasks/pyez_facts.py", line 11, in pyez_facts
    device = task.host.get_connection(CONNECTION_NAME, task.nornir.config)
  File "/Users/sohanr/PycharmProjects/Nornir_Auto/venv/lib/python3.9/site-packages/nornir/core/inventory.py", line 494, in get_connection
    self.open_connection(
  File "/Users/sohanr/PycharmProjects/Nornir_Auto/venv/lib/python3.9/site-packages/nornir/core/inventory.py", line 546, in open_connection
    conn_obj.open(
  File "/Users/sohanr/PycharmProjects/Nornir_Auto/venv/lib/python3.9/site-packages/nornir_pyez/plugins/connections/__init__.py", line 41, in open
    connection.open()
  File "/Users/sohanr/PycharmProjects/Nornir_Auto/venv/lib/python3.9/site-packages/jnpr/junos/device.py", line 1395, in open
    raise EzErrors.ConnectRefusedError(self)
jnpr.junos.exception.ConnectRefusedError: ConnectRefusedError(10.13.111.18)

2022-09-28 17:19:40,468 -  nornir.core -     INFO -        run() - Running task 'main_task' with args {} on 3 hosts
2022-09-28 17:20:35,796 -  nornir.core -     INFO -        run() - Running task 'pyez_facts' with args {} on 3 hosts
2022-09-28 17:20:39,224 -  nornir.core -     INFO -        run() - Running task 'main_task' with args {} on 3 hosts
2022-09-28 17:44:45,066 -  nornir.core -     INFO -        run() - Running task 'pyez_facts' with args {} on 4 hosts
2022-09-28 17:44:45,085 - nornir.core.task -    ERROR -      start() - Host 'vMX3': task 'pyez_facts' failed with traceback:
Traceback (most recent call last):
  File "/Users/sohanr/PycharmProjects/Nornir_Auto/venv/lib/python3.9/site-packages/jnpr/junos/device.py", line 1362, in open
    self._conn = netconf_ssh.connect(
  File "/Users/sohanr/PycharmProjects/Nornir_Auto/venv/lib/python3.9/site-packages/ncclient/manager.py", line 176, in connect
    return connect_ssh(*args, **kwds)
  File "/Users/sohanr/PycharmProjects/Nornir_Auto/venv/lib/python3.9/site-packages/ncclient/manager.py", line 143, in connect_ssh
    session.connect(*args, **kwds)
  File "/Users/sohanr/PycharmProjects/Nornir_Auto/venv/lib/python3.9/site-packages/ncclient/transport/ssh.py", line 277, in connect
    for res in socket.getaddrinfo(host, port, socket.AF_UNSPEC, socket.SOCK_STREAM):
  File "/Library/Developer/CommandLineTools/Library/Frameworks/Python3.framework/Versions/3.9/lib/python3.9/socket.py", line 953, in getaddrinfo
    for res in _socket.getaddrinfo(host, port, family, type, proto, flags):
socket.gaierror: [Errno 8] nodename nor servname provided, or not known

During handling of the above exception, another exception occurred:

Traceback (most recent call last):
  File "/Users/sohanr/PycharmProjects/Nornir_Auto/venv/lib/python3.9/site-packages/nornir/core/task.py", line 99, in start
    r = self.task(self, **self.params)
  File "/Users/sohanr/PycharmProjects/Nornir_Auto/venv/lib/python3.9/site-packages/nornir_pyez/plugins/tasks/pyez_facts.py", line 11, in pyez_facts
    device = task.host.get_connection(CONNECTION_NAME, task.nornir.config)
  File "/Users/sohanr/PycharmProjects/Nornir_Auto/venv/lib/python3.9/site-packages/nornir/core/inventory.py", line 494, in get_connection
    self.open_connection(
  File "/Users/sohanr/PycharmProjects/Nornir_Auto/venv/lib/python3.9/site-packages/nornir/core/inventory.py", line 546, in open_connection
    conn_obj.open(
  File "/Users/sohanr/PycharmProjects/Nornir_Auto/venv/lib/python3.9/site-packages/nornir_pyez/plugins/connections/__init__.py", line 41, in open
    connection.open()
  File "/Users/sohanr/PycharmProjects/Nornir_Auto/venv/lib/python3.9/site-packages/jnpr/junos/device.py", line 1412, in open
    raise EzErrors.ConnectUnknownHostError(self)
jnpr.junos.exception.ConnectUnknownHostError: ConnectUnknownHostError(66.129.234.214)

2022-09-28 17:44:46,848 - nornir.core.task -    ERROR -      start() - Host 'vMX1': task 'pyez_facts' failed with traceback:
Traceback (most recent call last):
  File "/Users/sohanr/PycharmProjects/Nornir_Auto/venv/lib/python3.9/site-packages/jnpr/junos/device.py", line 1362, in open
    self._conn = netconf_ssh.connect(
  File "/Users/sohanr/PycharmProjects/Nornir_Auto/venv/lib/python3.9/site-packages/ncclient/manager.py", line 176, in connect
    return connect_ssh(*args, **kwds)
  File "/Users/sohanr/PycharmProjects/Nornir_Auto/venv/lib/python3.9/site-packages/ncclient/manager.py", line 143, in connect_ssh
    session.connect(*args, **kwds)
  File "/Users/sohanr/PycharmProjects/Nornir_Auto/venv/lib/python3.9/site-packages/ncclient/transport/ssh.py", line 364, in connect
    self._auth(username, password, key_filenames, allow_agent, look_for_keys)
  File "/Users/sohanr/PycharmProjects/Nornir_Auto/venv/lib/python3.9/site-packages/ncclient/transport/ssh.py", line 480, in _auth
    raise AuthenticationError(repr(saved_exception))
ncclient.transport.errors.AuthenticationError: AuthenticationException('Authentication failed.')

During handling of the above exception, another exception occurred:

Traceback (most recent call last):
  File "/Users/sohanr/PycharmProjects/Nornir_Auto/venv/lib/python3.9/site-packages/nornir/core/task.py", line 99, in start
    r = self.task(self, **self.params)
  File "/Users/sohanr/PycharmProjects/Nornir_Auto/venv/lib/python3.9/site-packages/nornir_pyez/plugins/tasks/pyez_facts.py", line 11, in pyez_facts
    device = task.host.get_connection(CONNECTION_NAME, task.nornir.config)
  File "/Users/sohanr/PycharmProjects/Nornir_Auto/venv/lib/python3.9/site-packages/nornir/core/inventory.py", line 494, in get_connection
    self.open_connection(
  File "/Users/sohanr/PycharmProjects/Nornir_Auto/venv/lib/python3.9/site-packages/nornir/core/inventory.py", line 546, in open_connection
    conn_obj.open(
  File "/Users/sohanr/PycharmProjects/Nornir_Auto/venv/lib/python3.9/site-packages/nornir_pyez/plugins/connections/__init__.py", line 41, in open
    connection.open()
  File "/Users/sohanr/PycharmProjects/Nornir_Auto/venv/lib/python3.9/site-packages/jnpr/junos/device.py", line 1382, in open
    raise EzErrors.ConnectAuthError(self)
jnpr.junos.exception.ConnectAuthError: ConnectAuthError(66.129.234.214)

2022-09-28 17:44:46,851 - nornir.core.task -    ERROR -      start() - Host 'vMX2': task 'pyez_facts' failed with traceback:
Traceback (most recent call last):
  File "/Users/sohanr/PycharmProjects/Nornir_Auto/venv/lib/python3.9/site-packages/jnpr/junos/device.py", line 1362, in open
    self._conn = netconf_ssh.connect(
  File "/Users/sohanr/PycharmProjects/Nornir_Auto/venv/lib/python3.9/site-packages/ncclient/manager.py", line 176, in connect
    return connect_ssh(*args, **kwds)
  File "/Users/sohanr/PycharmProjects/Nornir_Auto/venv/lib/python3.9/site-packages/ncclient/manager.py", line 143, in connect_ssh
    session.connect(*args, **kwds)
  File "/Users/sohanr/PycharmProjects/Nornir_Auto/venv/lib/python3.9/site-packages/ncclient/transport/ssh.py", line 364, in connect
    self._auth(username, password, key_filenames, allow_agent, look_for_keys)
  File "/Users/sohanr/PycharmProjects/Nornir_Auto/venv/lib/python3.9/site-packages/ncclient/transport/ssh.py", line 480, in _auth
    raise AuthenticationError(repr(saved_exception))
ncclient.transport.errors.AuthenticationError: AuthenticationException('Authentication failed.')

During handling of the above exception, another exception occurred:

Traceback (most recent call last):
  File "/Users/sohanr/PycharmProjects/Nornir_Auto/venv/lib/python3.9/site-packages/nornir/core/task.py", line 99, in start
    r = self.task(self, **self.params)
  File "/Users/sohanr/PycharmProjects/Nornir_Auto/venv/lib/python3.9/site-packages/nornir_pyez/plugins/tasks/pyez_facts.py", line 11, in pyez_facts
    device = task.host.get_connection(CONNECTION_NAME, task.nornir.config)
  File "/Users/sohanr/PycharmProjects/Nornir_Auto/venv/lib/python3.9/site-packages/nornir/core/inventory.py", line 494, in get_connection
    self.open_connection(
  File "/Users/sohanr/PycharmProjects/Nornir_Auto/venv/lib/python3.9/site-packages/nornir/core/inventory.py", line 546, in open_connection
    conn_obj.open(
  File "/Users/sohanr/PycharmProjects/Nornir_Auto/venv/lib/python3.9/site-packages/nornir_pyez/plugins/connections/__init__.py", line 41, in open
    connection.open()
  File "/Users/sohanr/PycharmProjects/Nornir_Auto/venv/lib/python3.9/site-packages/jnpr/junos/device.py", line 1382, in open
    raise EzErrors.ConnectAuthError(self)
jnpr.junos.exception.ConnectAuthError: ConnectAuthError(66.129.234.214)

2022-09-28 17:45:15,071 - nornir.core.task -    ERROR -      start() - Host 'mx480-3': task 'pyez_facts' failed with traceback:
Traceback (most recent call last):
  File "/Users/sohanr/PycharmProjects/Nornir_Auto/venv/lib/python3.9/site-packages/jnpr/junos/device.py", line 1362, in open
    self._conn = netconf_ssh.connect(
  File "/Users/sohanr/PycharmProjects/Nornir_Auto/venv/lib/python3.9/site-packages/ncclient/manager.py", line 176, in connect
    return connect_ssh(*args, **kwds)
  File "/Users/sohanr/PycharmProjects/Nornir_Auto/venv/lib/python3.9/site-packages/ncclient/manager.py", line 143, in connect_ssh
    session.connect(*args, **kwds)
  File "/Users/sohanr/PycharmProjects/Nornir_Auto/venv/lib/python3.9/site-packages/ncclient/transport/ssh.py", line 293, in connect
    raise SSHError("Could not open socket to %s:%s" % (host, port))
ncclient.transport.errors.SSHError: Could not open socket to 10.13.110.60:830

During handling of the above exception, another exception occurred:

Traceback (most recent call last):
  File "/Users/sohanr/PycharmProjects/Nornir_Auto/venv/lib/python3.9/site-packages/nornir/core/task.py", line 99, in start
    r = self.task(self, **self.params)
  File "/Users/sohanr/PycharmProjects/Nornir_Auto/venv/lib/python3.9/site-packages/nornir_pyez/plugins/tasks/pyez_facts.py", line 11, in pyez_facts
    device = task.host.get_connection(CONNECTION_NAME, task.nornir.config)
  File "/Users/sohanr/PycharmProjects/Nornir_Auto/venv/lib/python3.9/site-packages/nornir/core/inventory.py", line 494, in get_connection
    self.open_connection(
  File "/Users/sohanr/PycharmProjects/Nornir_Auto/venv/lib/python3.9/site-packages/nornir/core/inventory.py", line 546, in open_connection
    conn_obj.open(
  File "/Users/sohanr/PycharmProjects/Nornir_Auto/venv/lib/python3.9/site-packages/nornir_pyez/plugins/connections/__init__.py", line 41, in open
    connection.open()
  File "/Users/sohanr/PycharmProjects/Nornir_Auto/venv/lib/python3.9/site-packages/jnpr/junos/device.py", line 1401, in open
    raise EzErrors.ConnectTimeoutError(self)
jnpr.junos.exception.ConnectTimeoutError: ConnectTimeoutError(10.13.110.60)

2022-09-28 17:45:15,081 -  nornir.core -     INFO -        run() - Running task 'main_task' with args {} on 4 hosts
2022-09-28 17:47:35,849 -  nornir.core -     INFO -        run() - Running task 'pyez_facts' with args {} on 3 hosts
2022-09-28 17:47:35,865 - nornir.core.task -    ERROR -      start() - Host 'vMX3': task 'pyez_facts' failed with traceback:
Traceback (most recent call last):
  File "/Users/sohanr/PycharmProjects/Nornir_Auto/venv/lib/python3.9/site-packages/jnpr/junos/device.py", line 1362, in open
    self._conn = netconf_ssh.connect(
  File "/Users/sohanr/PycharmProjects/Nornir_Auto/venv/lib/python3.9/site-packages/ncclient/manager.py", line 176, in connect
    return connect_ssh(*args, **kwds)
  File "/Users/sohanr/PycharmProjects/Nornir_Auto/venv/lib/python3.9/site-packages/ncclient/manager.py", line 143, in connect_ssh
    session.connect(*args, **kwds)
  File "/Users/sohanr/PycharmProjects/Nornir_Auto/venv/lib/python3.9/site-packages/ncclient/transport/ssh.py", line 277, in connect
    for res in socket.getaddrinfo(host, port, socket.AF_UNSPEC, socket.SOCK_STREAM):
  File "/Library/Developer/CommandLineTools/Library/Frameworks/Python3.framework/Versions/3.9/lib/python3.9/socket.py", line 953, in getaddrinfo
    for res in _socket.getaddrinfo(host, port, family, type, proto, flags):
socket.gaierror: [Errno 8] nodename nor servname provided, or not known

During handling of the above exception, another exception occurred:

Traceback (most recent call last):
  File "/Users/sohanr/PycharmProjects/Nornir_Auto/venv/lib/python3.9/site-packages/nornir/core/task.py", line 99, in start
    r = self.task(self, **self.params)
  File "/Users/sohanr/PycharmProjects/Nornir_Auto/venv/lib/python3.9/site-packages/nornir_pyez/plugins/tasks/pyez_facts.py", line 11, in pyez_facts
    device = task.host.get_connection(CONNECTION_NAME, task.nornir.config)
  File "/Users/sohanr/PycharmProjects/Nornir_Auto/venv/lib/python3.9/site-packages/nornir/core/inventory.py", line 494, in get_connection
    self.open_connection(
  File "/Users/sohanr/PycharmProjects/Nornir_Auto/venv/lib/python3.9/site-packages/nornir/core/inventory.py", line 546, in open_connection
    conn_obj.open(
  File "/Users/sohanr/PycharmProjects/Nornir_Auto/venv/lib/python3.9/site-packages/nornir_pyez/plugins/connections/__init__.py", line 41, in open
    connection.open()
  File "/Users/sohanr/PycharmProjects/Nornir_Auto/venv/lib/python3.9/site-packages/jnpr/junos/device.py", line 1412, in open
    raise EzErrors.ConnectUnknownHostError(self)
jnpr.junos.exception.ConnectUnknownHostError: ConnectUnknownHostError(66.129.234.214)

2022-09-28 17:47:38,911 -  nornir.core -     INFO -        run() - Running task 'main_task' with args {} on 3 hosts
2022-09-28 17:50:54,093 -  nornir.core -     INFO -        run() - Running task 'pyez_rpc' with args {'func': 'get-route-engine-information'} on 3 hosts
2022-09-28 17:50:54,131 - nornir.core.task -    ERROR -      start() - Host 'vMX3': task 'pyez_rpc' failed with traceback:
Traceback (most recent call last):
  File "/Users/sohanr/PycharmProjects/Nornir_Auto/venv/lib/python3.9/site-packages/jnpr/junos/device.py", line 1362, in open
    self._conn = netconf_ssh.connect(
  File "/Users/sohanr/PycharmProjects/Nornir_Auto/venv/lib/python3.9/site-packages/ncclient/manager.py", line 176, in connect
    return connect_ssh(*args, **kwds)
  File "/Users/sohanr/PycharmProjects/Nornir_Auto/venv/lib/python3.9/site-packages/ncclient/manager.py", line 143, in connect_ssh
    session.connect(*args, **kwds)
  File "/Users/sohanr/PycharmProjects/Nornir_Auto/venv/lib/python3.9/site-packages/ncclient/transport/ssh.py", line 277, in connect
    for res in socket.getaddrinfo(host, port, socket.AF_UNSPEC, socket.SOCK_STREAM):
  File "/Library/Developer/CommandLineTools/Library/Frameworks/Python3.framework/Versions/3.9/lib/python3.9/socket.py", line 953, in getaddrinfo
    for res in _socket.getaddrinfo(host, port, family, type, proto, flags):
socket.gaierror: [Errno 8] nodename nor servname provided, or not known

During handling of the above exception, another exception occurred:

Traceback (most recent call last):
  File "/Users/sohanr/PycharmProjects/Nornir_Auto/venv/lib/python3.9/site-packages/nornir/core/task.py", line 99, in start
    r = self.task(self, **self.params)
  File "/Users/sohanr/PycharmProjects/Nornir_Auto/venv/lib/python3.9/site-packages/nornir_pyez/plugins/tasks/pyez_rpc.py", line 16, in pyez_rpc
    device = task.host.get_connection(CONNECTION_NAME, task.nornir.config)
  File "/Users/sohanr/PycharmProjects/Nornir_Auto/venv/lib/python3.9/site-packages/nornir/core/inventory.py", line 494, in get_connection
    self.open_connection(
  File "/Users/sohanr/PycharmProjects/Nornir_Auto/venv/lib/python3.9/site-packages/nornir/core/inventory.py", line 546, in open_connection
    conn_obj.open(
  File "/Users/sohanr/PycharmProjects/Nornir_Auto/venv/lib/python3.9/site-packages/nornir_pyez/plugins/connections/__init__.py", line 41, in open
    connection.open()
  File "/Users/sohanr/PycharmProjects/Nornir_Auto/venv/lib/python3.9/site-packages/jnpr/junos/device.py", line 1412, in open
    raise EzErrors.ConnectUnknownHostError(self)
jnpr.junos.exception.ConnectUnknownHostError: ConnectUnknownHostError(66.129.234.214)

2022-09-28 17:54:32,001 -  nornir.core -     INFO -        run() - Running task 'pyez_facts' with args {} on 3 hosts
2022-09-28 17:54:32,015 - nornir.core.task -    ERROR -      start() - Host 'vMX3': task 'pyez_facts' failed with traceback:
Traceback (most recent call last):
  File "/Users/sohanr/PycharmProjects/Nornir_Auto/venv/lib/python3.9/site-packages/jnpr/junos/device.py", line 1362, in open
    self._conn = netconf_ssh.connect(
  File "/Users/sohanr/PycharmProjects/Nornir_Auto/venv/lib/python3.9/site-packages/ncclient/manager.py", line 176, in connect
    return connect_ssh(*args, **kwds)
  File "/Users/sohanr/PycharmProjects/Nornir_Auto/venv/lib/python3.9/site-packages/ncclient/manager.py", line 143, in connect_ssh
    session.connect(*args, **kwds)
  File "/Users/sohanr/PycharmProjects/Nornir_Auto/venv/lib/python3.9/site-packages/ncclient/transport/ssh.py", line 277, in connect
    for res in socket.getaddrinfo(host, port, socket.AF_UNSPEC, socket.SOCK_STREAM):
  File "/Library/Developer/CommandLineTools/Library/Frameworks/Python3.framework/Versions/3.9/lib/python3.9/socket.py", line 953, in getaddrinfo
    for res in _socket.getaddrinfo(host, port, family, type, proto, flags):
socket.gaierror: [Errno 8] nodename nor servname provided, or not known

During handling of the above exception, another exception occurred:

Traceback (most recent call last):
  File "/Users/sohanr/PycharmProjects/Nornir_Auto/venv/lib/python3.9/site-packages/nornir/core/task.py", line 99, in start
    r = self.task(self, **self.params)
  File "/Users/sohanr/PycharmProjects/Nornir_Auto/venv/lib/python3.9/site-packages/nornir_pyez/plugins/tasks/pyez_facts.py", line 11, in pyez_facts
    device = task.host.get_connection(CONNECTION_NAME, task.nornir.config)
  File "/Users/sohanr/PycharmProjects/Nornir_Auto/venv/lib/python3.9/site-packages/nornir/core/inventory.py", line 494, in get_connection
    self.open_connection(
  File "/Users/sohanr/PycharmProjects/Nornir_Auto/venv/lib/python3.9/site-packages/nornir/core/inventory.py", line 546, in open_connection
    conn_obj.open(
  File "/Users/sohanr/PycharmProjects/Nornir_Auto/venv/lib/python3.9/site-packages/nornir_pyez/plugins/connections/__init__.py", line 41, in open
    connection.open()
  File "/Users/sohanr/PycharmProjects/Nornir_Auto/venv/lib/python3.9/site-packages/jnpr/junos/device.py", line 1412, in open
    raise EzErrors.ConnectUnknownHostError(self)
jnpr.junos.exception.ConnectUnknownHostError: ConnectUnknownHostError(66.129.234.214)

2022-09-28 17:54:34,962 -  nornir.core -     INFO -        run() - Running task 'main_task' with args {} on 3 hosts
2022-09-28 17:56:12,262 -  nornir.core -     INFO -        run() - Running task 'pyez_facts' with args {} on 3 hosts
2022-09-28 17:56:12,278 - nornir.core.task -    ERROR -      start() - Host 'vMX3': task 'pyez_facts' failed with traceback:
Traceback (most recent call last):
  File "/Users/sohanr/PycharmProjects/Nornir_Auto/venv/lib/python3.9/site-packages/jnpr/junos/device.py", line 1362, in open
    self._conn = netconf_ssh.connect(
  File "/Users/sohanr/PycharmProjects/Nornir_Auto/venv/lib/python3.9/site-packages/ncclient/manager.py", line 176, in connect
    return connect_ssh(*args, **kwds)
  File "/Users/sohanr/PycharmProjects/Nornir_Auto/venv/lib/python3.9/site-packages/ncclient/manager.py", line 143, in connect_ssh
    session.connect(*args, **kwds)
  File "/Users/sohanr/PycharmProjects/Nornir_Auto/venv/lib/python3.9/site-packages/ncclient/transport/ssh.py", line 277, in connect
    for res in socket.getaddrinfo(host, port, socket.AF_UNSPEC, socket.SOCK_STREAM):
  File "/Library/Developer/CommandLineTools/Library/Frameworks/Python3.framework/Versions/3.9/lib/python3.9/socket.py", line 953, in getaddrinfo
    for res in _socket.getaddrinfo(host, port, family, type, proto, flags):
socket.gaierror: [Errno 8] nodename nor servname provided, or not known

During handling of the above exception, another exception occurred:

Traceback (most recent call last):
  File "/Users/sohanr/PycharmProjects/Nornir_Auto/venv/lib/python3.9/site-packages/nornir/core/task.py", line 99, in start
    r = self.task(self, **self.params)
  File "/Users/sohanr/PycharmProjects/Nornir_Auto/venv/lib/python3.9/site-packages/nornir_pyez/plugins/tasks/pyez_facts.py", line 11, in pyez_facts
    device = task.host.get_connection(CONNECTION_NAME, task.nornir.config)
  File "/Users/sohanr/PycharmProjects/Nornir_Auto/venv/lib/python3.9/site-packages/nornir/core/inventory.py", line 494, in get_connection
    self.open_connection(
  File "/Users/sohanr/PycharmProjects/Nornir_Auto/venv/lib/python3.9/site-packages/nornir/core/inventory.py", line 546, in open_connection
    conn_obj.open(
  File "/Users/sohanr/PycharmProjects/Nornir_Auto/venv/lib/python3.9/site-packages/nornir_pyez/plugins/connections/__init__.py", line 41, in open
    connection.open()
  File "/Users/sohanr/PycharmProjects/Nornir_Auto/venv/lib/python3.9/site-packages/jnpr/junos/device.py", line 1412, in open
    raise EzErrors.ConnectUnknownHostError(self)
jnpr.junos.exception.ConnectUnknownHostError: ConnectUnknownHostError(66.129.234.214)

2022-09-28 17:56:15,299 -  nornir.core -     INFO -        run() - Running task 'main_task' with args {} on 3 hosts
2022-09-28 18:01:42,989 -  nornir.core -     INFO -        run() - Running task 'pyez_facts' with args {} on 3 hosts
2022-09-28 18:01:43,004 - nornir.core.task -    ERROR -      start() - Host 'vMX3': task 'pyez_facts' failed with traceback:
Traceback (most recent call last):
  File "/Users/sohanr/PycharmProjects/Nornir_Auto/venv/lib/python3.9/site-packages/jnpr/junos/device.py", line 1362, in open
    self._conn = netconf_ssh.connect(
  File "/Users/sohanr/PycharmProjects/Nornir_Auto/venv/lib/python3.9/site-packages/ncclient/manager.py", line 176, in connect
    return connect_ssh(*args, **kwds)
  File "/Users/sohanr/PycharmProjects/Nornir_Auto/venv/lib/python3.9/site-packages/ncclient/manager.py", line 143, in connect_ssh
    session.connect(*args, **kwds)
  File "/Users/sohanr/PycharmProjects/Nornir_Auto/venv/lib/python3.9/site-packages/ncclient/transport/ssh.py", line 277, in connect
    for res in socket.getaddrinfo(host, port, socket.AF_UNSPEC, socket.SOCK_STREAM):
  File "/Library/Developer/CommandLineTools/Library/Frameworks/Python3.framework/Versions/3.9/lib/python3.9/socket.py", line 953, in getaddrinfo
    for res in _socket.getaddrinfo(host, port, family, type, proto, flags):
socket.gaierror: [Errno 8] nodename nor servname provided, or not known

During handling of the above exception, another exception occurred:

Traceback (most recent call last):
  File "/Users/sohanr/PycharmProjects/Nornir_Auto/venv/lib/python3.9/site-packages/nornir/core/task.py", line 99, in start
    r = self.task(self, **self.params)
  File "/Users/sohanr/PycharmProjects/Nornir_Auto/venv/lib/python3.9/site-packages/nornir_pyez/plugins/tasks/pyez_facts.py", line 11, in pyez_facts
    device = task.host.get_connection(CONNECTION_NAME, task.nornir.config)
  File "/Users/sohanr/PycharmProjects/Nornir_Auto/venv/lib/python3.9/site-packages/nornir/core/inventory.py", line 494, in get_connection
    self.open_connection(
  File "/Users/sohanr/PycharmProjects/Nornir_Auto/venv/lib/python3.9/site-packages/nornir/core/inventory.py", line 546, in open_connection
    conn_obj.open(
  File "/Users/sohanr/PycharmProjects/Nornir_Auto/venv/lib/python3.9/site-packages/nornir_pyez/plugins/connections/__init__.py", line 41, in open
    connection.open()
  File "/Users/sohanr/PycharmProjects/Nornir_Auto/venv/lib/python3.9/site-packages/jnpr/junos/device.py", line 1412, in open
    raise EzErrors.ConnectUnknownHostError(self)
jnpr.junos.exception.ConnectUnknownHostError: ConnectUnknownHostError(66.129.234.214)

2022-09-28 18:01:44,299 - nornir.core.task -    ERROR -      start() - Host 'vMX1': task 'pyez_facts' failed with traceback:
Traceback (most recent call last):
  File "/Users/sohanr/PycharmProjects/Nornir_Auto/venv/lib/python3.9/site-packages/paramiko/transport.py", line 2271, in _check_banner
    buf = self.packetizer.readline(timeout)
  File "/Users/sohanr/PycharmProjects/Nornir_Auto/venv/lib/python3.9/site-packages/paramiko/packet.py", line 380, in readline
    buf += self._read_timeout(timeout)
  File "/Users/sohanr/PycharmProjects/Nornir_Auto/venv/lib/python3.9/site-packages/paramiko/packet.py", line 607, in _read_timeout
    x = self.__socket.recv(128)
ConnectionResetError: [Errno 54] Connection reset by peer

During handling of the above exception, another exception occurred:

Traceback (most recent call last):
  File "/Users/sohanr/PycharmProjects/Nornir_Auto/venv/lib/python3.9/site-packages/ncclient/transport/ssh.py", line 331, in connect
    self._transport.start_client()
  File "/Users/sohanr/PycharmProjects/Nornir_Auto/venv/lib/python3.9/site-packages/paramiko/transport.py", line 699, in start_client
    raise e
  File "/Users/sohanr/PycharmProjects/Nornir_Auto/venv/lib/python3.9/site-packages/paramiko/transport.py", line 2094, in run
    self._check_banner()
  File "/Users/sohanr/PycharmProjects/Nornir_Auto/venv/lib/python3.9/site-packages/paramiko/transport.py", line 2275, in _check_banner
    raise SSHException(
paramiko.ssh_exception.SSHException: Error reading SSH protocol banner[Errno 54] Connection reset by peer

During handling of the above exception, another exception occurred:

Traceback (most recent call last):
  File "/Users/sohanr/PycharmProjects/Nornir_Auto/venv/lib/python3.9/site-packages/jnpr/junos/device.py", line 1362, in open
    self._conn = netconf_ssh.connect(
  File "/Users/sohanr/PycharmProjects/Nornir_Auto/venv/lib/python3.9/site-packages/ncclient/manager.py", line 176, in connect
    return connect_ssh(*args, **kwds)
  File "/Users/sohanr/PycharmProjects/Nornir_Auto/venv/lib/python3.9/site-packages/ncclient/manager.py", line 143, in connect_ssh
    session.connect(*args, **kwds)
  File "/Users/sohanr/PycharmProjects/Nornir_Auto/venv/lib/python3.9/site-packages/ncclient/transport/ssh.py", line 333, in connect
    raise SSHError('Negotiation failed: %s' % e)
ncclient.transport.errors.SSHError: Negotiation failed: Error reading SSH protocol banner[Errno 54] Connection reset by peer

During handling of the above exception, another exception occurred:

Traceback (most recent call last):
  File "/Users/sohanr/PycharmProjects/Nornir_Auto/venv/lib/python3.9/site-packages/nornir/core/task.py", line 99, in start
    r = self.task(self, **self.params)
  File "/Users/sohanr/PycharmProjects/Nornir_Auto/venv/lib/python3.9/site-packages/nornir_pyez/plugins/tasks/pyez_facts.py", line 11, in pyez_facts
    device = task.host.get_connection(CONNECTION_NAME, task.nornir.config)
  File "/Users/sohanr/PycharmProjects/Nornir_Auto/venv/lib/python3.9/site-packages/nornir/core/inventory.py", line 494, in get_connection
    self.open_connection(
  File "/Users/sohanr/PycharmProjects/Nornir_Auto/venv/lib/python3.9/site-packages/nornir/core/inventory.py", line 546, in open_connection
    conn_obj.open(
  File "/Users/sohanr/PycharmProjects/Nornir_Auto/venv/lib/python3.9/site-packages/nornir_pyez/plugins/connections/__init__.py", line 41, in open
    connection.open()
  File "/Users/sohanr/PycharmProjects/Nornir_Auto/venv/lib/python3.9/site-packages/jnpr/junos/device.py", line 1395, in open
    raise EzErrors.ConnectRefusedError(self)
jnpr.junos.exception.ConnectRefusedError: ConnectRefusedError(66.129.234.214)

2022-09-28 18:01:44,300 - nornir.core.task -    ERROR -      start() - Host 'vMX2': task 'pyez_facts' failed with traceback:
Traceback (most recent call last):
  File "/Users/sohanr/PycharmProjects/Nornir_Auto/venv/lib/python3.9/site-packages/paramiko/transport.py", line 2271, in _check_banner
    buf = self.packetizer.readline(timeout)
  File "/Users/sohanr/PycharmProjects/Nornir_Auto/venv/lib/python3.9/site-packages/paramiko/packet.py", line 380, in readline
    buf += self._read_timeout(timeout)
  File "/Users/sohanr/PycharmProjects/Nornir_Auto/venv/lib/python3.9/site-packages/paramiko/packet.py", line 607, in _read_timeout
    x = self.__socket.recv(128)
ConnectionResetError: [Errno 54] Connection reset by peer

During handling of the above exception, another exception occurred:

Traceback (most recent call last):
  File "/Users/sohanr/PycharmProjects/Nornir_Auto/venv/lib/python3.9/site-packages/ncclient/transport/ssh.py", line 331, in connect
    self._transport.start_client()
  File "/Users/sohanr/PycharmProjects/Nornir_Auto/venv/lib/python3.9/site-packages/paramiko/transport.py", line 699, in start_client
    raise e
  File "/Users/sohanr/PycharmProjects/Nornir_Auto/venv/lib/python3.9/site-packages/paramiko/transport.py", line 2094, in run
    self._check_banner()
  File "/Users/sohanr/PycharmProjects/Nornir_Auto/venv/lib/python3.9/site-packages/paramiko/transport.py", line 2275, in _check_banner
    raise SSHException(
paramiko.ssh_exception.SSHException: Error reading SSH protocol banner[Errno 54] Connection reset by peer

During handling of the above exception, another exception occurred:

Traceback (most recent call last):
  File "/Users/sohanr/PycharmProjects/Nornir_Auto/venv/lib/python3.9/site-packages/jnpr/junos/device.py", line 1362, in open
    self._conn = netconf_ssh.connect(
  File "/Users/sohanr/PycharmProjects/Nornir_Auto/venv/lib/python3.9/site-packages/ncclient/manager.py", line 176, in connect
    return connect_ssh(*args, **kwds)
  File "/Users/sohanr/PycharmProjects/Nornir_Auto/venv/lib/python3.9/site-packages/ncclient/manager.py", line 143, in connect_ssh
    session.connect(*args, **kwds)
  File "/Users/sohanr/PycharmProjects/Nornir_Auto/venv/lib/python3.9/site-packages/ncclient/transport/ssh.py", line 333, in connect
    raise SSHError('Negotiation failed: %s' % e)
ncclient.transport.errors.SSHError: Negotiation failed: Error reading SSH protocol banner[Errno 54] Connection reset by peer

During handling of the above exception, another exception occurred:

Traceback (most recent call last):
  File "/Users/sohanr/PycharmProjects/Nornir_Auto/venv/lib/python3.9/site-packages/nornir/core/task.py", line 99, in start
    r = self.task(self, **self.params)
  File "/Users/sohanr/PycharmProjects/Nornir_Auto/venv/lib/python3.9/site-packages/nornir_pyez/plugins/tasks/pyez_facts.py", line 11, in pyez_facts
    device = task.host.get_connection(CONNECTION_NAME, task.nornir.config)
  File "/Users/sohanr/PycharmProjects/Nornir_Auto/venv/lib/python3.9/site-packages/nornir/core/inventory.py", line 494, in get_connection
    self.open_connection(
  File "/Users/sohanr/PycharmProjects/Nornir_Auto/venv/lib/python3.9/site-packages/nornir/core/inventory.py", line 546, in open_connection
    conn_obj.open(
  File "/Users/sohanr/PycharmProjects/Nornir_Auto/venv/lib/python3.9/site-packages/nornir_pyez/plugins/connections/__init__.py", line 41, in open
    connection.open()
  File "/Users/sohanr/PycharmProjects/Nornir_Auto/venv/lib/python3.9/site-packages/jnpr/junos/device.py", line 1395, in open
    raise EzErrors.ConnectRefusedError(self)
jnpr.junos.exception.ConnectRefusedError: ConnectRefusedError(66.129.234.214)

2022-09-28 18:01:44,304 -  nornir.core -     INFO -        run() - Running task 'main_task' with args {} on 3 hosts
2022-09-28 18:02:16,761 -  nornir.core -     INFO -        run() - Running task 'pyez_facts' with args {} on 3 hosts
2022-09-28 18:02:16,779 - nornir.core.task -    ERROR -      start() - Host 'vMX3': task 'pyez_facts' failed with traceback:
Traceback (most recent call last):
  File "/Users/sohanr/PycharmProjects/Nornir_Auto/venv/lib/python3.9/site-packages/jnpr/junos/device.py", line 1362, in open
    self._conn = netconf_ssh.connect(
  File "/Users/sohanr/PycharmProjects/Nornir_Auto/venv/lib/python3.9/site-packages/ncclient/manager.py", line 176, in connect
    return connect_ssh(*args, **kwds)
  File "/Users/sohanr/PycharmProjects/Nornir_Auto/venv/lib/python3.9/site-packages/ncclient/manager.py", line 143, in connect_ssh
    session.connect(*args, **kwds)
  File "/Users/sohanr/PycharmProjects/Nornir_Auto/venv/lib/python3.9/site-packages/ncclient/transport/ssh.py", line 277, in connect
    for res in socket.getaddrinfo(host, port, socket.AF_UNSPEC, socket.SOCK_STREAM):
  File "/Library/Developer/CommandLineTools/Library/Frameworks/Python3.framework/Versions/3.9/lib/python3.9/socket.py", line 953, in getaddrinfo
    for res in _socket.getaddrinfo(host, port, family, type, proto, flags):
socket.gaierror: [Errno 8] nodename nor servname provided, or not known

During handling of the above exception, another exception occurred:

Traceback (most recent call last):
  File "/Users/sohanr/PycharmProjects/Nornir_Auto/venv/lib/python3.9/site-packages/nornir/core/task.py", line 99, in start
    r = self.task(self, **self.params)
  File "/Users/sohanr/PycharmProjects/Nornir_Auto/venv/lib/python3.9/site-packages/nornir_pyez/plugins/tasks/pyez_facts.py", line 11, in pyez_facts
    device = task.host.get_connection(CONNECTION_NAME, task.nornir.config)
  File "/Users/sohanr/PycharmProjects/Nornir_Auto/venv/lib/python3.9/site-packages/nornir/core/inventory.py", line 494, in get_connection
    self.open_connection(
  File "/Users/sohanr/PycharmProjects/Nornir_Auto/venv/lib/python3.9/site-packages/nornir/core/inventory.py", line 546, in open_connection
    conn_obj.open(
  File "/Users/sohanr/PycharmProjects/Nornir_Auto/venv/lib/python3.9/site-packages/nornir_pyez/plugins/connections/__init__.py", line 41, in open
    connection.open()
  File "/Users/sohanr/PycharmProjects/Nornir_Auto/venv/lib/python3.9/site-packages/jnpr/junos/device.py", line 1412, in open
    raise EzErrors.ConnectUnknownHostError(self)
jnpr.junos.exception.ConnectUnknownHostError: ConnectUnknownHostError(66.129.234.214)

2022-09-28 18:02:19,848 -  nornir.core -     INFO -        run() - Running task 'main_task' with args {} on 3 hosts
2022-09-28 18:04:59,373 -  nornir.core -     INFO -        run() - Running task 'pyez_facts' with args {} on 3 hosts
2022-09-28 18:04:59,388 - nornir.core.task -    ERROR -      start() - Host 'vMX3': task 'pyez_facts' failed with traceback:
Traceback (most recent call last):
  File "/Users/sohanr/PycharmProjects/Nornir_Auto/venv/lib/python3.9/site-packages/jnpr/junos/device.py", line 1362, in open
    self._conn = netconf_ssh.connect(
  File "/Users/sohanr/PycharmProjects/Nornir_Auto/venv/lib/python3.9/site-packages/ncclient/manager.py", line 176, in connect
    return connect_ssh(*args, **kwds)
  File "/Users/sohanr/PycharmProjects/Nornir_Auto/venv/lib/python3.9/site-packages/ncclient/manager.py", line 143, in connect_ssh
    session.connect(*args, **kwds)
  File "/Users/sohanr/PycharmProjects/Nornir_Auto/venv/lib/python3.9/site-packages/ncclient/transport/ssh.py", line 277, in connect
    for res in socket.getaddrinfo(host, port, socket.AF_UNSPEC, socket.SOCK_STREAM):
  File "/Library/Developer/CommandLineTools/Library/Frameworks/Python3.framework/Versions/3.9/lib/python3.9/socket.py", line 953, in getaddrinfo
    for res in _socket.getaddrinfo(host, port, family, type, proto, flags):
socket.gaierror: [Errno 8] nodename nor servname provided, or not known

During handling of the above exception, another exception occurred:

Traceback (most recent call last):
  File "/Users/sohanr/PycharmProjects/Nornir_Auto/venv/lib/python3.9/site-packages/nornir/core/task.py", line 99, in start
    r = self.task(self, **self.params)
  File "/Users/sohanr/PycharmProjects/Nornir_Auto/venv/lib/python3.9/site-packages/nornir_pyez/plugins/tasks/pyez_facts.py", line 11, in pyez_facts
    device = task.host.get_connection(CONNECTION_NAME, task.nornir.config)
  File "/Users/sohanr/PycharmProjects/Nornir_Auto/venv/lib/python3.9/site-packages/nornir/core/inventory.py", line 494, in get_connection
    self.open_connection(
  File "/Users/sohanr/PycharmProjects/Nornir_Auto/venv/lib/python3.9/site-packages/nornir/core/inventory.py", line 546, in open_connection
    conn_obj.open(
  File "/Users/sohanr/PycharmProjects/Nornir_Auto/venv/lib/python3.9/site-packages/nornir_pyez/plugins/connections/__init__.py", line 41, in open
    connection.open()
  File "/Users/sohanr/PycharmProjects/Nornir_Auto/venv/lib/python3.9/site-packages/jnpr/junos/device.py", line 1412, in open
    raise EzErrors.ConnectUnknownHostError(self)
jnpr.junos.exception.ConnectUnknownHostError: ConnectUnknownHostError(66.129.234.214)

2022-09-28 18:05:02,270 -  nornir.core -     INFO -        run() - Running task 'main_task' with args {} on 3 hosts
2022-09-28 18:18:44,965 -  nornir.core -     INFO -        run() - Running task 'main_task' with args {} on 3 hosts
2022-09-28 18:18:44,982 - nornir.core.task -    ERROR -      start() - Host 'vMX1': task 'main_task' failed with traceback:
Traceback (most recent call last):
  File "/Users/sohanr/PycharmProjects/Nornir_Auto/venv/lib/python3.9/site-packages/nornir/core/task.py", line 99, in start
    r = self.task(self, **self.params)
  File "<stdin>", line 2, in main_task
NameError: name 'pyez_facts' is not defined

2022-09-28 18:18:44,983 - nornir.core.task -    ERROR -      start() - Host 'vMX2': task 'main_task' failed with traceback:
Traceback (most recent call last):
  File "/Users/sohanr/PycharmProjects/Nornir_Auto/venv/lib/python3.9/site-packages/nornir/core/task.py", line 99, in start
    r = self.task(self, **self.params)
  File "<stdin>", line 2, in main_task
NameError: name 'pyez_facts' is not defined

2022-09-28 18:21:37,905 -  nornir.core -     INFO -        run() - Running task 'pyez_facts' with args {} on 3 hosts
2022-09-28 18:21:37,923 - nornir.core.task -    ERROR -      start() - Host 'vMX3': task 'pyez_facts' failed with traceback:
Traceback (most recent call last):
  File "/Users/sohanr/PycharmProjects/Nornir_Auto/venv/lib/python3.9/site-packages/jnpr/junos/device.py", line 1362, in open
    self._conn = netconf_ssh.connect(
  File "/Users/sohanr/PycharmProjects/Nornir_Auto/venv/lib/python3.9/site-packages/ncclient/manager.py", line 176, in connect
    return connect_ssh(*args, **kwds)
  File "/Users/sohanr/PycharmProjects/Nornir_Auto/venv/lib/python3.9/site-packages/ncclient/manager.py", line 143, in connect_ssh
    session.connect(*args, **kwds)
  File "/Users/sohanr/PycharmProjects/Nornir_Auto/venv/lib/python3.9/site-packages/ncclient/transport/ssh.py", line 277, in connect
    for res in socket.getaddrinfo(host, port, socket.AF_UNSPEC, socket.SOCK_STREAM):
  File "/Library/Developer/CommandLineTools/Library/Frameworks/Python3.framework/Versions/3.9/lib/python3.9/socket.py", line 953, in getaddrinfo
    for res in _socket.getaddrinfo(host, port, family, type, proto, flags):
socket.gaierror: [Errno 8] nodename nor servname provided, or not known

During handling of the above exception, another exception occurred:

Traceback (most recent call last):
  File "/Users/sohanr/PycharmProjects/Nornir_Auto/venv/lib/python3.9/site-packages/nornir/core/task.py", line 99, in start
    r = self.task(self, **self.params)
  File "/Users/sohanr/PycharmProjects/Nornir_Auto/venv/lib/python3.9/site-packages/nornir_pyez/plugins/tasks/pyez_facts.py", line 11, in pyez_facts
    device = task.host.get_connection(CONNECTION_NAME, task.nornir.config)
  File "/Users/sohanr/PycharmProjects/Nornir_Auto/venv/lib/python3.9/site-packages/nornir/core/inventory.py", line 494, in get_connection
    self.open_connection(
  File "/Users/sohanr/PycharmProjects/Nornir_Auto/venv/lib/python3.9/site-packages/nornir/core/inventory.py", line 546, in open_connection
    conn_obj.open(
  File "/Users/sohanr/PycharmProjects/Nornir_Auto/venv/lib/python3.9/site-packages/nornir_pyez/plugins/connections/__init__.py", line 41, in open
    connection.open()
  File "/Users/sohanr/PycharmProjects/Nornir_Auto/venv/lib/python3.9/site-packages/jnpr/junos/device.py", line 1412, in open
    raise EzErrors.ConnectUnknownHostError(self)
jnpr.junos.exception.ConnectUnknownHostError: ConnectUnknownHostError(66.129.234.214)

2022-09-28 18:21:41,003 -  nornir.core -     INFO -        run() - Running task 'main_task' with args {} on 3 hosts
2022-09-28 18:22:59,188 -  nornir.core -     INFO -        run() - Running task 'pyez_facts' with args {} on 3 hosts
2022-09-28 18:23:02,140 -  nornir.core -     INFO -        run() - Running task 'main_task' with args {} on 3 hosts
2022-09-28 18:30:14,768 -  nornir.core -     INFO -        run() - Running task 'main_task' with args {} on 3 hosts
2022-09-28 18:30:14,788 - nornir.core.task -    ERROR -      start() - Host 'vMX3': task 'facts' failed with traceback:
Traceback (most recent call last):
  File "/Users/sohanr/PycharmProjects/Nornir_Auto/venv/lib/python3.9/site-packages/jnpr/junos/device.py", line 1362, in open
    self._conn = netconf_ssh.connect(
  File "/Users/sohanr/PycharmProjects/Nornir_Auto/venv/lib/python3.9/site-packages/ncclient/manager.py", line 176, in connect
    return connect_ssh(*args, **kwds)
  File "/Users/sohanr/PycharmProjects/Nornir_Auto/venv/lib/python3.9/site-packages/ncclient/manager.py", line 143, in connect_ssh
    session.connect(*args, **kwds)
  File "/Users/sohanr/PycharmProjects/Nornir_Auto/venv/lib/python3.9/site-packages/ncclient/transport/ssh.py", line 277, in connect
    for res in socket.getaddrinfo(host, port, socket.AF_UNSPEC, socket.SOCK_STREAM):
  File "/Library/Developer/CommandLineTools/Library/Frameworks/Python3.framework/Versions/3.9/lib/python3.9/socket.py", line 953, in getaddrinfo
    for res in _socket.getaddrinfo(host, port, family, type, proto, flags):
socket.gaierror: [Errno 8] nodename nor servname provided, or not known

During handling of the above exception, another exception occurred:

Traceback (most recent call last):
  File "/Users/sohanr/PycharmProjects/Nornir_Auto/venv/lib/python3.9/site-packages/nornir/core/task.py", line 99, in start
    r = self.task(self, **self.params)
  File "/Users/sohanr/PycharmProjects/Nornir_Auto/venv/lib/python3.9/site-packages/nornir_pyez/plugins/tasks/pyez_facts.py", line 11, in pyez_facts
    device = task.host.get_connection(CONNECTION_NAME, task.nornir.config)
  File "/Users/sohanr/PycharmProjects/Nornir_Auto/venv/lib/python3.9/site-packages/nornir/core/inventory.py", line 494, in get_connection
    self.open_connection(
  File "/Users/sohanr/PycharmProjects/Nornir_Auto/venv/lib/python3.9/site-packages/nornir/core/inventory.py", line 546, in open_connection
    conn_obj.open(
  File "/Users/sohanr/PycharmProjects/Nornir_Auto/venv/lib/python3.9/site-packages/nornir_pyez/plugins/connections/__init__.py", line 41, in open
    connection.open()
  File "/Users/sohanr/PycharmProjects/Nornir_Auto/venv/lib/python3.9/site-packages/jnpr/junos/device.py", line 1412, in open
    raise EzErrors.ConnectUnknownHostError(self)
jnpr.junos.exception.ConnectUnknownHostError: ConnectUnknownHostError(66.129.234.214)

2022-09-28 18:30:14,788 - nornir.core.task -    ERROR -      start() - Host 'vMX3': task 'main_task' failed with traceback:
Traceback (most recent call last):
  File "/Users/sohanr/PycharmProjects/Nornir_Auto/venv/lib/python3.9/site-packages/nornir/core/task.py", line 99, in start
    r = self.task(self, **self.params)
  File "/Users/sohanr/PycharmProjects/Nornir_Auto/dashboard/dashboard.py", line 46, in main_task
    task.run(name='facts', task=pyez_facts)
  File "/Users/sohanr/PycharmProjects/Nornir_Auto/venv/lib/python3.9/site-packages/nornir/core/task.py", line 174, in run
    raise NornirSubTaskError(task=run_task, result=r)
nornir.core.exceptions.NornirSubTaskError: Subtask: facts (failed)


2022-09-28 18:32:18,578 -  nornir.core -     INFO -        run() - Running task 'main_task' with args {} on 3 hosts
2022-09-28 18:32:18,593 - nornir.core.task -    ERROR -      start() - Host 'vMX3': task 'facts' failed with traceback:
Traceback (most recent call last):
  File "/Users/sohanr/PycharmProjects/Nornir_Auto/venv/lib/python3.9/site-packages/jnpr/junos/device.py", line 1362, in open
    self._conn = netconf_ssh.connect(
  File "/Users/sohanr/PycharmProjects/Nornir_Auto/venv/lib/python3.9/site-packages/ncclient/manager.py", line 176, in connect
    return connect_ssh(*args, **kwds)
  File "/Users/sohanr/PycharmProjects/Nornir_Auto/venv/lib/python3.9/site-packages/ncclient/manager.py", line 143, in connect_ssh
    session.connect(*args, **kwds)
  File "/Users/sohanr/PycharmProjects/Nornir_Auto/venv/lib/python3.9/site-packages/ncclient/transport/ssh.py", line 277, in connect
    for res in socket.getaddrinfo(host, port, socket.AF_UNSPEC, socket.SOCK_STREAM):
  File "/Library/Developer/CommandLineTools/Library/Frameworks/Python3.framework/Versions/3.9/lib/python3.9/socket.py", line 953, in getaddrinfo
    for res in _socket.getaddrinfo(host, port, family, type, proto, flags):
socket.gaierror: [Errno 8] nodename nor servname provided, or not known

During handling of the above exception, another exception occurred:

Traceback (most recent call last):
  File "/Users/sohanr/PycharmProjects/Nornir_Auto/venv/lib/python3.9/site-packages/nornir/core/task.py", line 99, in start
    r = self.task(self, **self.params)
  File "/Users/sohanr/PycharmProjects/Nornir_Auto/venv/lib/python3.9/site-packages/nornir_pyez/plugins/tasks/pyez_facts.py", line 11, in pyez_facts
    device = task.host.get_connection(CONNECTION_NAME, task.nornir.config)
  File "/Users/sohanr/PycharmProjects/Nornir_Auto/venv/lib/python3.9/site-packages/nornir/core/inventory.py", line 494, in get_connection
    self.open_connection(
  File "/Users/sohanr/PycharmProjects/Nornir_Auto/venv/lib/python3.9/site-packages/nornir/core/inventory.py", line 546, in open_connection
    conn_obj.open(
  File "/Users/sohanr/PycharmProjects/Nornir_Auto/venv/lib/python3.9/site-packages/nornir_pyez/plugins/connections/__init__.py", line 41, in open
    connection.open()
  File "/Users/sohanr/PycharmProjects/Nornir_Auto/venv/lib/python3.9/site-packages/jnpr/junos/device.py", line 1412, in open
    raise EzErrors.ConnectUnknownHostError(self)
jnpr.junos.exception.ConnectUnknownHostError: ConnectUnknownHostError(66.129.234.214)

2022-09-28 18:32:18,593 - nornir.core.task -    ERROR -      start() - Host 'vMX3': task 'main_task' failed with traceback:
Traceback (most recent call last):
  File "/Users/sohanr/PycharmProjects/Nornir_Auto/venv/lib/python3.9/site-packages/nornir/core/task.py", line 99, in start
    r = self.task(self, **self.params)
  File "/Users/sohanr/PycharmProjects/Nornir_Auto/dashboard/dashboard.py", line 46, in main_task
    task.run(name='facts', task=pyez_facts)
  File "/Users/sohanr/PycharmProjects/Nornir_Auto/venv/lib/python3.9/site-packages/nornir/core/task.py", line 174, in run
    raise NornirSubTaskError(task=run_task, result=r)
nornir.core.exceptions.NornirSubTaskError: Subtask: facts (failed)


2022-09-28 18:35:18,382 -  nornir.core -     INFO -        run() - Running task 'main_task' with args {} on 3 hosts
2022-09-28 18:35:18,398 - nornir.core.task -    ERROR -      start() - Host 'vMX3': task 'facts' failed with traceback:
Traceback (most recent call last):
  File "/Users/sohanr/PycharmProjects/Nornir_Auto/venv/lib/python3.9/site-packages/jnpr/junos/device.py", line 1362, in open
    self._conn = netconf_ssh.connect(
  File "/Users/sohanr/PycharmProjects/Nornir_Auto/venv/lib/python3.9/site-packages/ncclient/manager.py", line 176, in connect
    return connect_ssh(*args, **kwds)
  File "/Users/sohanr/PycharmProjects/Nornir_Auto/venv/lib/python3.9/site-packages/ncclient/manager.py", line 143, in connect_ssh
    session.connect(*args, **kwds)
  File "/Users/sohanr/PycharmProjects/Nornir_Auto/venv/lib/python3.9/site-packages/ncclient/transport/ssh.py", line 277, in connect
    for res in socket.getaddrinfo(host, port, socket.AF_UNSPEC, socket.SOCK_STREAM):
  File "/Library/Developer/CommandLineTools/Library/Frameworks/Python3.framework/Versions/3.9/lib/python3.9/socket.py", line 953, in getaddrinfo
    for res in _socket.getaddrinfo(host, port, family, type, proto, flags):
socket.gaierror: [Errno 8] nodename nor servname provided, or not known

During handling of the above exception, another exception occurred:

Traceback (most recent call last):
  File "/Users/sohanr/PycharmProjects/Nornir_Auto/venv/lib/python3.9/site-packages/nornir/core/task.py", line 99, in start
    r = self.task(self, **self.params)
  File "/Users/sohanr/PycharmProjects/Nornir_Auto/venv/lib/python3.9/site-packages/nornir_pyez/plugins/tasks/pyez_facts.py", line 11, in pyez_facts
    device = task.host.get_connection(CONNECTION_NAME, task.nornir.config)
  File "/Users/sohanr/PycharmProjects/Nornir_Auto/venv/lib/python3.9/site-packages/nornir/core/inventory.py", line 494, in get_connection
    self.open_connection(
  File "/Users/sohanr/PycharmProjects/Nornir_Auto/venv/lib/python3.9/site-packages/nornir/core/inventory.py", line 546, in open_connection
    conn_obj.open(
  File "/Users/sohanr/PycharmProjects/Nornir_Auto/venv/lib/python3.9/site-packages/nornir_pyez/plugins/connections/__init__.py", line 41, in open
    connection.open()
  File "/Users/sohanr/PycharmProjects/Nornir_Auto/venv/lib/python3.9/site-packages/jnpr/junos/device.py", line 1412, in open
    raise EzErrors.ConnectUnknownHostError(self)
jnpr.junos.exception.ConnectUnknownHostError: ConnectUnknownHostError(66.129.234.214)

2022-09-28 18:35:18,398 - nornir.core.task -    ERROR -      start() - Host 'vMX3': task 'main_task' failed with traceback:
Traceback (most recent call last):
  File "/Users/sohanr/PycharmProjects/Nornir_Auto/venv/lib/python3.9/site-packages/nornir/core/task.py", line 99, in start
    r = self.task(self, **self.params)
  File "/Users/sohanr/PycharmProjects/Nornir_Auto/dashboard/dashboard.py", line 46, in main_task
    task.run(name='facts', task=pyez_facts)
  File "/Users/sohanr/PycharmProjects/Nornir_Auto/venv/lib/python3.9/site-packages/nornir/core/task.py", line 174, in run
    raise NornirSubTaskError(task=run_task, result=r)
nornir.core.exceptions.NornirSubTaskError: Subtask: facts (failed)


2022-09-28 18:38:20,743 -  nornir.core -     INFO -        run() - Running task 'pyez_facts' with args {} on 3 hosts
2022-09-28 18:38:44,071 -  nornir.core -     INFO -        run() - Running task 'pyez_facts' with args {} on 3 hosts
2022-09-28 18:38:44,099 - nornir.core.task -    ERROR -      start() - Host 'vMX3': task 'pyez_facts' failed with traceback:
Traceback (most recent call last):
  File "/Users/sohanr/PycharmProjects/Nornir_Auto/venv/lib/python3.9/site-packages/jnpr/junos/device.py", line 1362, in open
    self._conn = netconf_ssh.connect(
  File "/Users/sohanr/PycharmProjects/Nornir_Auto/venv/lib/python3.9/site-packages/ncclient/manager.py", line 176, in connect
    return connect_ssh(*args, **kwds)
  File "/Users/sohanr/PycharmProjects/Nornir_Auto/venv/lib/python3.9/site-packages/ncclient/manager.py", line 143, in connect_ssh
    session.connect(*args, **kwds)
  File "/Users/sohanr/PycharmProjects/Nornir_Auto/venv/lib/python3.9/site-packages/ncclient/transport/ssh.py", line 277, in connect
    for res in socket.getaddrinfo(host, port, socket.AF_UNSPEC, socket.SOCK_STREAM):
  File "/Library/Developer/CommandLineTools/Library/Frameworks/Python3.framework/Versions/3.9/lib/python3.9/socket.py", line 953, in getaddrinfo
    for res in _socket.getaddrinfo(host, port, family, type, proto, flags):
socket.gaierror: [Errno 8] nodename nor servname provided, or not known

During handling of the above exception, another exception occurred:

Traceback (most recent call last):
  File "/Users/sohanr/PycharmProjects/Nornir_Auto/venv/lib/python3.9/site-packages/nornir/core/task.py", line 99, in start
    r = self.task(self, **self.params)
  File "/Users/sohanr/PycharmProjects/Nornir_Auto/venv/lib/python3.9/site-packages/nornir_pyez/plugins/tasks/pyez_facts.py", line 11, in pyez_facts
    device = task.host.get_connection(CONNECTION_NAME, task.nornir.config)
  File "/Users/sohanr/PycharmProjects/Nornir_Auto/venv/lib/python3.9/site-packages/nornir/core/inventory.py", line 494, in get_connection
    self.open_connection(
  File "/Users/sohanr/PycharmProjects/Nornir_Auto/venv/lib/python3.9/site-packages/nornir/core/inventory.py", line 546, in open_connection
    conn_obj.open(
  File "/Users/sohanr/PycharmProjects/Nornir_Auto/venv/lib/python3.9/site-packages/nornir_pyez/plugins/connections/__init__.py", line 41, in open
    connection.open()
  File "/Users/sohanr/PycharmProjects/Nornir_Auto/venv/lib/python3.9/site-packages/jnpr/junos/device.py", line 1412, in open
    raise EzErrors.ConnectUnknownHostError(self)
jnpr.junos.exception.ConnectUnknownHostError: ConnectUnknownHostError(66.129.234.214)

2022-09-28 18:43:10,642 -  nornir.core -     INFO -        run() - Running task 'main_task' with args {} on 3 hosts
2022-09-28 18:43:10,657 - nornir.core.task -    ERROR -      start() - Host 'vMX3': task 'facts' failed with traceback:
Traceback (most recent call last):
  File "/Users/sohanr/PycharmProjects/Nornir_Auto/venv/lib/python3.9/site-packages/jnpr/junos/device.py", line 1362, in open
    self._conn = netconf_ssh.connect(
  File "/Users/sohanr/PycharmProjects/Nornir_Auto/venv/lib/python3.9/site-packages/ncclient/manager.py", line 176, in connect
    return connect_ssh(*args, **kwds)
  File "/Users/sohanr/PycharmProjects/Nornir_Auto/venv/lib/python3.9/site-packages/ncclient/manager.py", line 143, in connect_ssh
    session.connect(*args, **kwds)
  File "/Users/sohanr/PycharmProjects/Nornir_Auto/venv/lib/python3.9/site-packages/ncclient/transport/ssh.py", line 277, in connect
    for res in socket.getaddrinfo(host, port, socket.AF_UNSPEC, socket.SOCK_STREAM):
  File "/Library/Developer/CommandLineTools/Library/Frameworks/Python3.framework/Versions/3.9/lib/python3.9/socket.py", line 953, in getaddrinfo
    for res in _socket.getaddrinfo(host, port, family, type, proto, flags):
socket.gaierror: [Errno 8] nodename nor servname provided, or not known

During handling of the above exception, another exception occurred:

Traceback (most recent call last):
  File "/Users/sohanr/PycharmProjects/Nornir_Auto/venv/lib/python3.9/site-packages/nornir/core/task.py", line 99, in start
    r = self.task(self, **self.params)
  File "/Users/sohanr/PycharmProjects/Nornir_Auto/venv/lib/python3.9/site-packages/nornir_pyez/plugins/tasks/pyez_facts.py", line 11, in pyez_facts
    device = task.host.get_connection(CONNECTION_NAME, task.nornir.config)
  File "/Users/sohanr/PycharmProjects/Nornir_Auto/venv/lib/python3.9/site-packages/nornir/core/inventory.py", line 494, in get_connection
    self.open_connection(
  File "/Users/sohanr/PycharmProjects/Nornir_Auto/venv/lib/python3.9/site-packages/nornir/core/inventory.py", line 546, in open_connection
    conn_obj.open(
  File "/Users/sohanr/PycharmProjects/Nornir_Auto/venv/lib/python3.9/site-packages/nornir_pyez/plugins/connections/__init__.py", line 41, in open
    connection.open()
  File "/Users/sohanr/PycharmProjects/Nornir_Auto/venv/lib/python3.9/site-packages/jnpr/junos/device.py", line 1412, in open
    raise EzErrors.ConnectUnknownHostError(self)
jnpr.junos.exception.ConnectUnknownHostError: ConnectUnknownHostError(66.129.234.214)

2022-09-28 18:43:10,657 - nornir.core.task -    ERROR -      start() - Host 'vMX3': task 'main_task' failed with traceback:
Traceback (most recent call last):
  File "/Users/sohanr/PycharmProjects/Nornir_Auto/venv/lib/python3.9/site-packages/nornir/core/task.py", line 99, in start
    r = self.task(self, **self.params)
  File "/Users/sohanr/PycharmProjects/Nornir_Auto/dashboard/dashboard.py", line 46, in main_task
    task.run(name='facts', task=pyez_facts)
  File "/Users/sohanr/PycharmProjects/Nornir_Auto/venv/lib/python3.9/site-packages/nornir/core/task.py", line 174, in run
    raise NornirSubTaskError(task=run_task, result=r)
nornir.core.exceptions.NornirSubTaskError: Subtask: facts (failed)


2022-09-28 18:44:14,373 -  nornir.core -     INFO -        run() - Running task 'main_task' with args {} on 3 hosts
2022-09-28 18:44:14,391 - nornir.core.task -    ERROR -      start() - Host 'vMX3': task 'facts' failed with traceback:
Traceback (most recent call last):
  File "/Users/sohanr/PycharmProjects/Nornir_Auto/venv/lib/python3.9/site-packages/jnpr/junos/device.py", line 1362, in open
    self._conn = netconf_ssh.connect(
  File "/Users/sohanr/PycharmProjects/Nornir_Auto/venv/lib/python3.9/site-packages/ncclient/manager.py", line 176, in connect
    return connect_ssh(*args, **kwds)
  File "/Users/sohanr/PycharmProjects/Nornir_Auto/venv/lib/python3.9/site-packages/ncclient/manager.py", line 143, in connect_ssh
    session.connect(*args, **kwds)
  File "/Users/sohanr/PycharmProjects/Nornir_Auto/venv/lib/python3.9/site-packages/ncclient/transport/ssh.py", line 277, in connect
    for res in socket.getaddrinfo(host, port, socket.AF_UNSPEC, socket.SOCK_STREAM):
  File "/Library/Developer/CommandLineTools/Library/Frameworks/Python3.framework/Versions/3.9/lib/python3.9/socket.py", line 953, in getaddrinfo
    for res in _socket.getaddrinfo(host, port, family, type, proto, flags):
socket.gaierror: [Errno 8] nodename nor servname provided, or not known

During handling of the above exception, another exception occurred:

Traceback (most recent call last):
  File "/Users/sohanr/PycharmProjects/Nornir_Auto/venv/lib/python3.9/site-packages/nornir/core/task.py", line 99, in start
    r = self.task(self, **self.params)
  File "/Users/sohanr/PycharmProjects/Nornir_Auto/venv/lib/python3.9/site-packages/nornir_pyez/plugins/tasks/pyez_facts.py", line 11, in pyez_facts
    device = task.host.get_connection(CONNECTION_NAME, task.nornir.config)
  File "/Users/sohanr/PycharmProjects/Nornir_Auto/venv/lib/python3.9/site-packages/nornir/core/inventory.py", line 494, in get_connection
    self.open_connection(
  File "/Users/sohanr/PycharmProjects/Nornir_Auto/venv/lib/python3.9/site-packages/nornir/core/inventory.py", line 546, in open_connection
    conn_obj.open(
  File "/Users/sohanr/PycharmProjects/Nornir_Auto/venv/lib/python3.9/site-packages/nornir_pyez/plugins/connections/__init__.py", line 41, in open
    connection.open()
  File "/Users/sohanr/PycharmProjects/Nornir_Auto/venv/lib/python3.9/site-packages/jnpr/junos/device.py", line 1412, in open
    raise EzErrors.ConnectUnknownHostError(self)
jnpr.junos.exception.ConnectUnknownHostError: ConnectUnknownHostError(66.129.234.214)

2022-09-28 18:44:14,391 - nornir.core.task -    ERROR -      start() - Host 'vMX3': task 'main_task' failed with traceback:
Traceback (most recent call last):
  File "/Users/sohanr/PycharmProjects/Nornir_Auto/venv/lib/python3.9/site-packages/nornir/core/task.py", line 99, in start
    r = self.task(self, **self.params)
  File "/Users/sohanr/PycharmProjects/Nornir_Auto/dashboard/dashboard.py", line 46, in main_task
    task.run(name='facts', task=pyez_facts)
  File "/Users/sohanr/PycharmProjects/Nornir_Auto/venv/lib/python3.9/site-packages/nornir/core/task.py", line 174, in run
    raise NornirSubTaskError(task=run_task, result=r)
nornir.core.exceptions.NornirSubTaskError: Subtask: facts (failed)


2022-09-28 18:45:03,844 -  nornir.core -     INFO -        run() - Running task 'main_task' with args {} on 3 hosts
2022-09-28 18:45:03,859 - nornir.core.task -    ERROR -      start() - Host 'vMX3': task 'facts' failed with traceback:
Traceback (most recent call last):
  File "/Users/sohanr/PycharmProjects/Nornir_Auto/venv/lib/python3.9/site-packages/jnpr/junos/device.py", line 1362, in open
    self._conn = netconf_ssh.connect(
  File "/Users/sohanr/PycharmProjects/Nornir_Auto/venv/lib/python3.9/site-packages/ncclient/manager.py", line 176, in connect
    return connect_ssh(*args, **kwds)
  File "/Users/sohanr/PycharmProjects/Nornir_Auto/venv/lib/python3.9/site-packages/ncclient/manager.py", line 143, in connect_ssh
    session.connect(*args, **kwds)
  File "/Users/sohanr/PycharmProjects/Nornir_Auto/venv/lib/python3.9/site-packages/ncclient/transport/ssh.py", line 277, in connect
    for res in socket.getaddrinfo(host, port, socket.AF_UNSPEC, socket.SOCK_STREAM):
  File "/Library/Developer/CommandLineTools/Library/Frameworks/Python3.framework/Versions/3.9/lib/python3.9/socket.py", line 953, in getaddrinfo
    for res in _socket.getaddrinfo(host, port, family, type, proto, flags):
socket.gaierror: [Errno 8] nodename nor servname provided, or not known

During handling of the above exception, another exception occurred:

Traceback (most recent call last):
  File "/Users/sohanr/PycharmProjects/Nornir_Auto/venv/lib/python3.9/site-packages/nornir/core/task.py", line 99, in start
    r = self.task(self, **self.params)
  File "/Users/sohanr/PycharmProjects/Nornir_Auto/venv/lib/python3.9/site-packages/nornir_pyez/plugins/tasks/pyez_facts.py", line 11, in pyez_facts
    device = task.host.get_connection(CONNECTION_NAME, task.nornir.config)
  File "/Users/sohanr/PycharmProjects/Nornir_Auto/venv/lib/python3.9/site-packages/nornir/core/inventory.py", line 494, in get_connection
    self.open_connection(
  File "/Users/sohanr/PycharmProjects/Nornir_Auto/venv/lib/python3.9/site-packages/nornir/core/inventory.py", line 546, in open_connection
    conn_obj.open(
  File "/Users/sohanr/PycharmProjects/Nornir_Auto/venv/lib/python3.9/site-packages/nornir_pyez/plugins/connections/__init__.py", line 41, in open
    connection.open()
  File "/Users/sohanr/PycharmProjects/Nornir_Auto/venv/lib/python3.9/site-packages/jnpr/junos/device.py", line 1412, in open
    raise EzErrors.ConnectUnknownHostError(self)
jnpr.junos.exception.ConnectUnknownHostError: ConnectUnknownHostError(66.129.234.214)

2022-09-28 18:45:03,860 - nornir.core.task -    ERROR -      start() - Host 'vMX3': task 'main_task' failed with traceback:
Traceback (most recent call last):
  File "/Users/sohanr/PycharmProjects/Nornir_Auto/venv/lib/python3.9/site-packages/nornir/core/task.py", line 99, in start
    r = self.task(self, **self.params)
  File "/Users/sohanr/PycharmProjects/Nornir_Auto/dashboard/dashboard.py", line 46, in main_task
    task.run(name='facts', task=pyez_facts)
  File "/Users/sohanr/PycharmProjects/Nornir_Auto/venv/lib/python3.9/site-packages/nornir/core/task.py", line 174, in run
    raise NornirSubTaskError(task=run_task, result=r)
nornir.core.exceptions.NornirSubTaskError: Subtask: facts (failed)


2022-09-28 18:46:59,212 -  nornir.core -     INFO -        run() - Running task 'main_task' with args {} on 3 hosts
2022-09-28 18:46:59,230 - nornir.core.task -    ERROR -      start() - Host 'vMX3': task 'facts' failed with traceback:
Traceback (most recent call last):
  File "/Users/sohanr/PycharmProjects/Nornir_Auto/venv/lib/python3.9/site-packages/jnpr/junos/device.py", line 1362, in open
    self._conn = netconf_ssh.connect(
  File "/Users/sohanr/PycharmProjects/Nornir_Auto/venv/lib/python3.9/site-packages/ncclient/manager.py", line 176, in connect
    return connect_ssh(*args, **kwds)
  File "/Users/sohanr/PycharmProjects/Nornir_Auto/venv/lib/python3.9/site-packages/ncclient/manager.py", line 143, in connect_ssh
    session.connect(*args, **kwds)
  File "/Users/sohanr/PycharmProjects/Nornir_Auto/venv/lib/python3.9/site-packages/ncclient/transport/ssh.py", line 277, in connect
    for res in socket.getaddrinfo(host, port, socket.AF_UNSPEC, socket.SOCK_STREAM):
  File "/Library/Developer/CommandLineTools/Library/Frameworks/Python3.framework/Versions/3.9/lib/python3.9/socket.py", line 953, in getaddrinfo
    for res in _socket.getaddrinfo(host, port, family, type, proto, flags):
socket.gaierror: [Errno 8] nodename nor servname provided, or not known

During handling of the above exception, another exception occurred:

Traceback (most recent call last):
  File "/Users/sohanr/PycharmProjects/Nornir_Auto/venv/lib/python3.9/site-packages/nornir/core/task.py", line 99, in start
    r = self.task(self, **self.params)
  File "/Users/sohanr/PycharmProjects/Nornir_Auto/venv/lib/python3.9/site-packages/nornir_pyez/plugins/tasks/pyez_facts.py", line 11, in pyez_facts
    device = task.host.get_connection(CONNECTION_NAME, task.nornir.config)
  File "/Users/sohanr/PycharmProjects/Nornir_Auto/venv/lib/python3.9/site-packages/nornir/core/inventory.py", line 494, in get_connection
    self.open_connection(
  File "/Users/sohanr/PycharmProjects/Nornir_Auto/venv/lib/python3.9/site-packages/nornir/core/inventory.py", line 546, in open_connection
    conn_obj.open(
  File "/Users/sohanr/PycharmProjects/Nornir_Auto/venv/lib/python3.9/site-packages/nornir_pyez/plugins/connections/__init__.py", line 41, in open
    connection.open()
  File "/Users/sohanr/PycharmProjects/Nornir_Auto/venv/lib/python3.9/site-packages/jnpr/junos/device.py", line 1412, in open
    raise EzErrors.ConnectUnknownHostError(self)
jnpr.junos.exception.ConnectUnknownHostError: ConnectUnknownHostError(66.129.234.214)

2022-09-28 18:46:59,230 - nornir.core.task -    ERROR -      start() - Host 'vMX3': task 'main_task' failed with traceback:
Traceback (most recent call last):
  File "/Users/sohanr/PycharmProjects/Nornir_Auto/venv/lib/python3.9/site-packages/nornir/core/task.py", line 99, in start
    r = self.task(self, **self.params)
  File "/Users/sohanr/PycharmProjects/Nornir_Auto/dashboard/dashboard.py", line 46, in main_task
    task.run(name='facts', task=pyez_facts)
  File "/Users/sohanr/PycharmProjects/Nornir_Auto/venv/lib/python3.9/site-packages/nornir/core/task.py", line 174, in run
    raise NornirSubTaskError(task=run_task, result=r)
nornir.core.exceptions.NornirSubTaskError: Subtask: facts (failed)


2022-09-28 18:49:38,587 -  nornir.core -     INFO -        run() - Running task 'main_task' with args {} on 3 hosts
2022-09-28 19:07:18,320 -  nornir.core -     INFO -        run() - Running task 'main_task' with args {} on 3 hosts
2022-09-28 22:10:50,955 -  nornir.core -     INFO -        run() - Running task 'main_task' with args {} on 3 hosts
2022-09-28 22:27:58,846 -  nornir.core -     INFO -        run() - Running task 'main_task' with args {} on 3 hosts
2022-09-28 22:27:59,843 - nornir.core.task -    ERROR -      start() - Host 'vMX3': task 'facts' failed with traceback:
Traceback (most recent call last):
  File "/Users/sohanr/PycharmProjects/Nornir_Auto/venv/lib/python3.9/site-packages/paramiko/transport.py", line 2271, in _check_banner
    buf = self.packetizer.readline(timeout)
  File "/Users/sohanr/PycharmProjects/Nornir_Auto/venv/lib/python3.9/site-packages/paramiko/packet.py", line 380, in readline
    buf += self._read_timeout(timeout)
  File "/Users/sohanr/PycharmProjects/Nornir_Auto/venv/lib/python3.9/site-packages/paramiko/packet.py", line 607, in _read_timeout
    x = self.__socket.recv(128)
ConnectionResetError: [Errno 54] Connection reset by peer

During handling of the above exception, another exception occurred:

Traceback (most recent call last):
  File "/Users/sohanr/PycharmProjects/Nornir_Auto/venv/lib/python3.9/site-packages/ncclient/transport/ssh.py", line 331, in connect
    self._transport.start_client()
  File "/Users/sohanr/PycharmProjects/Nornir_Auto/venv/lib/python3.9/site-packages/paramiko/transport.py", line 699, in start_client
    raise e
  File "/Users/sohanr/PycharmProjects/Nornir_Auto/venv/lib/python3.9/site-packages/paramiko/transport.py", line 2094, in run
    self._check_banner()
  File "/Users/sohanr/PycharmProjects/Nornir_Auto/venv/lib/python3.9/site-packages/paramiko/transport.py", line 2275, in _check_banner
    raise SSHException(
paramiko.ssh_exception.SSHException: Error reading SSH protocol banner[Errno 54] Connection reset by peer

During handling of the above exception, another exception occurred:

Traceback (most recent call last):
  File "/Users/sohanr/PycharmProjects/Nornir_Auto/venv/lib/python3.9/site-packages/jnpr/junos/device.py", line 1362, in open
    self._conn = netconf_ssh.connect(
  File "/Users/sohanr/PycharmProjects/Nornir_Auto/venv/lib/python3.9/site-packages/ncclient/manager.py", line 176, in connect
    return connect_ssh(*args, **kwds)
  File "/Users/sohanr/PycharmProjects/Nornir_Auto/venv/lib/python3.9/site-packages/ncclient/manager.py", line 143, in connect_ssh
    session.connect(*args, **kwds)
  File "/Users/sohanr/PycharmProjects/Nornir_Auto/venv/lib/python3.9/site-packages/ncclient/transport/ssh.py", line 333, in connect
    raise SSHError('Negotiation failed: %s' % e)
ncclient.transport.errors.SSHError: Negotiation failed: Error reading SSH protocol banner[Errno 54] Connection reset by peer

During handling of the above exception, another exception occurred:

Traceback (most recent call last):
  File "/Users/sohanr/PycharmProjects/Nornir_Auto/venv/lib/python3.9/site-packages/nornir/core/task.py", line 99, in start
    r = self.task(self, **self.params)
  File "/Users/sohanr/PycharmProjects/Nornir_Auto/venv/lib/python3.9/site-packages/nornir_pyez/plugins/tasks/pyez_facts.py", line 11, in pyez_facts
    device = task.host.get_connection(CONNECTION_NAME, task.nornir.config)
  File "/Users/sohanr/PycharmProjects/Nornir_Auto/venv/lib/python3.9/site-packages/nornir/core/inventory.py", line 494, in get_connection
    self.open_connection(
  File "/Users/sohanr/PycharmProjects/Nornir_Auto/venv/lib/python3.9/site-packages/nornir/core/inventory.py", line 546, in open_connection
    conn_obj.open(
  File "/Users/sohanr/PycharmProjects/Nornir_Auto/venv/lib/python3.9/site-packages/nornir_pyez/plugins/connections/__init__.py", line 41, in open
    connection.open()
  File "/Users/sohanr/PycharmProjects/Nornir_Auto/venv/lib/python3.9/site-packages/jnpr/junos/device.py", line 1395, in open
    raise EzErrors.ConnectRefusedError(self)
jnpr.junos.exception.ConnectRefusedError: ConnectRefusedError(66.129.234.214)

2022-09-28 22:27:59,843 - nornir.core.task -    ERROR -      start() - Host 'vMX1': task 'facts' failed with traceback:
Traceback (most recent call last):
  File "/Users/sohanr/PycharmProjects/Nornir_Auto/venv/lib/python3.9/site-packages/paramiko/transport.py", line 2271, in _check_banner
    buf = self.packetizer.readline(timeout)
  File "/Users/sohanr/PycharmProjects/Nornir_Auto/venv/lib/python3.9/site-packages/paramiko/packet.py", line 380, in readline
    buf += self._read_timeout(timeout)
  File "/Users/sohanr/PycharmProjects/Nornir_Auto/venv/lib/python3.9/site-packages/paramiko/packet.py", line 607, in _read_timeout
    x = self.__socket.recv(128)
ConnectionResetError: [Errno 54] Connection reset by peer

During handling of the above exception, another exception occurred:

Traceback (most recent call last):
  File "/Users/sohanr/PycharmProjects/Nornir_Auto/venv/lib/python3.9/site-packages/ncclient/transport/ssh.py", line 331, in connect
    self._transport.start_client()
  File "/Users/sohanr/PycharmProjects/Nornir_Auto/venv/lib/python3.9/site-packages/paramiko/transport.py", line 699, in start_client
    raise e
  File "/Users/sohanr/PycharmProjects/Nornir_Auto/venv/lib/python3.9/site-packages/paramiko/transport.py", line 2094, in run
    self._check_banner()
  File "/Users/sohanr/PycharmProjects/Nornir_Auto/venv/lib/python3.9/site-packages/paramiko/transport.py", line 2275, in _check_banner
    raise SSHException(
paramiko.ssh_exception.SSHException: Error reading SSH protocol banner[Errno 54] Connection reset by peer

During handling of the above exception, another exception occurred:

Traceback (most recent call last):
  File "/Users/sohanr/PycharmProjects/Nornir_Auto/venv/lib/python3.9/site-packages/jnpr/junos/device.py", line 1362, in open
    self._conn = netconf_ssh.connect(
  File "/Users/sohanr/PycharmProjects/Nornir_Auto/venv/lib/python3.9/site-packages/ncclient/manager.py", line 176, in connect
    return connect_ssh(*args, **kwds)
  File "/Users/sohanr/PycharmProjects/Nornir_Auto/venv/lib/python3.9/site-packages/ncclient/manager.py", line 143, in connect_ssh
    session.connect(*args, **kwds)
  File "/Users/sohanr/PycharmProjects/Nornir_Auto/venv/lib/python3.9/site-packages/ncclient/transport/ssh.py", line 333, in connect
    raise SSHError('Negotiation failed: %s' % e)
ncclient.transport.errors.SSHError: Negotiation failed: Error reading SSH protocol banner[Errno 54] Connection reset by peer

During handling of the above exception, another exception occurred:

Traceback (most recent call last):
  File "/Users/sohanr/PycharmProjects/Nornir_Auto/venv/lib/python3.9/site-packages/nornir/core/task.py", line 99, in start
    r = self.task(self, **self.params)
  File "/Users/sohanr/PycharmProjects/Nornir_Auto/venv/lib/python3.9/site-packages/nornir_pyez/plugins/tasks/pyez_facts.py", line 11, in pyez_facts
    device = task.host.get_connection(CONNECTION_NAME, task.nornir.config)
  File "/Users/sohanr/PycharmProjects/Nornir_Auto/venv/lib/python3.9/site-packages/nornir/core/inventory.py", line 494, in get_connection
    self.open_connection(
  File "/Users/sohanr/PycharmProjects/Nornir_Auto/venv/lib/python3.9/site-packages/nornir/core/inventory.py", line 546, in open_connection
    conn_obj.open(
  File "/Users/sohanr/PycharmProjects/Nornir_Auto/venv/lib/python3.9/site-packages/nornir_pyez/plugins/connections/__init__.py", line 41, in open
    connection.open()
  File "/Users/sohanr/PycharmProjects/Nornir_Auto/venv/lib/python3.9/site-packages/jnpr/junos/device.py", line 1395, in open
    raise EzErrors.ConnectRefusedError(self)
jnpr.junos.exception.ConnectRefusedError: ConnectRefusedError(66.129.234.214)

2022-09-28 22:27:59,844 - nornir.core.task -    ERROR -      start() - Host 'vMX2': task 'facts' failed with traceback:
Traceback (most recent call last):
  File "/Users/sohanr/PycharmProjects/Nornir_Auto/venv/lib/python3.9/site-packages/paramiko/transport.py", line 2271, in _check_banner
    buf = self.packetizer.readline(timeout)
  File "/Users/sohanr/PycharmProjects/Nornir_Auto/venv/lib/python3.9/site-packages/paramiko/packet.py", line 380, in readline
    buf += self._read_timeout(timeout)
  File "/Users/sohanr/PycharmProjects/Nornir_Auto/venv/lib/python3.9/site-packages/paramiko/packet.py", line 607, in _read_timeout
    x = self.__socket.recv(128)
ConnectionResetError: [Errno 54] Connection reset by peer

During handling of the above exception, another exception occurred:

Traceback (most recent call last):
  File "/Users/sohanr/PycharmProjects/Nornir_Auto/venv/lib/python3.9/site-packages/ncclient/transport/ssh.py", line 331, in connect
    self._transport.start_client()
  File "/Users/sohanr/PycharmProjects/Nornir_Auto/venv/lib/python3.9/site-packages/paramiko/transport.py", line 699, in start_client
    raise e
  File "/Users/sohanr/PycharmProjects/Nornir_Auto/venv/lib/python3.9/site-packages/paramiko/transport.py", line 2094, in run
    self._check_banner()
  File "/Users/sohanr/PycharmProjects/Nornir_Auto/venv/lib/python3.9/site-packages/paramiko/transport.py", line 2275, in _check_banner
    raise SSHException(
paramiko.ssh_exception.SSHException: Error reading SSH protocol banner[Errno 54] Connection reset by peer

During handling of the above exception, another exception occurred:

Traceback (most recent call last):
  File "/Users/sohanr/PycharmProjects/Nornir_Auto/venv/lib/python3.9/site-packages/jnpr/junos/device.py", line 1362, in open
    self._conn = netconf_ssh.connect(
  File "/Users/sohanr/PycharmProjects/Nornir_Auto/venv/lib/python3.9/site-packages/ncclient/manager.py", line 176, in connect
    return connect_ssh(*args, **kwds)
  File "/Users/sohanr/PycharmProjects/Nornir_Auto/venv/lib/python3.9/site-packages/ncclient/manager.py", line 143, in connect_ssh
    session.connect(*args, **kwds)
  File "/Users/sohanr/PycharmProjects/Nornir_Auto/venv/lib/python3.9/site-packages/ncclient/transport/ssh.py", line 333, in connect
    raise SSHError('Negotiation failed: %s' % e)
ncclient.transport.errors.SSHError: Negotiation failed: Error reading SSH protocol banner[Errno 54] Connection reset by peer

During handling of the above exception, another exception occurred:

Traceback (most recent call last):
  File "/Users/sohanr/PycharmProjects/Nornir_Auto/venv/lib/python3.9/site-packages/nornir/core/task.py", line 99, in start
    r = self.task(self, **self.params)
  File "/Users/sohanr/PycharmProjects/Nornir_Auto/venv/lib/python3.9/site-packages/nornir_pyez/plugins/tasks/pyez_facts.py", line 11, in pyez_facts
    device = task.host.get_connection(CONNECTION_NAME, task.nornir.config)
  File "/Users/sohanr/PycharmProjects/Nornir_Auto/venv/lib/python3.9/site-packages/nornir/core/inventory.py", line 494, in get_connection
    self.open_connection(
  File "/Users/sohanr/PycharmProjects/Nornir_Auto/venv/lib/python3.9/site-packages/nornir/core/inventory.py", line 546, in open_connection
    conn_obj.open(
  File "/Users/sohanr/PycharmProjects/Nornir_Auto/venv/lib/python3.9/site-packages/nornir_pyez/plugins/connections/__init__.py", line 41, in open
    connection.open()
  File "/Users/sohanr/PycharmProjects/Nornir_Auto/venv/lib/python3.9/site-packages/jnpr/junos/device.py", line 1395, in open
    raise EzErrors.ConnectRefusedError(self)
jnpr.junos.exception.ConnectRefusedError: ConnectRefusedError(66.129.234.214)

2022-09-28 22:27:59,844 - nornir.core.task -    ERROR -      start() - Host 'vMX3': task 'main_task' failed with traceback:
Traceback (most recent call last):
  File "/Users/sohanr/PycharmProjects/Nornir_Auto/venv/lib/python3.9/site-packages/nornir/core/task.py", line 99, in start
    r = self.task(self, **self.params)
  File "/Users/sohanr/PycharmProjects/Nornir_Auto/dashboard/dashboard.py", line 47, in main_task
    task.run(name='facts', task=pyez_facts)
  File "/Users/sohanr/PycharmProjects/Nornir_Auto/venv/lib/python3.9/site-packages/nornir/core/task.py", line 174, in run
    raise NornirSubTaskError(task=run_task, result=r)
nornir.core.exceptions.NornirSubTaskError: Subtask: facts (failed)


2022-09-28 22:27:59,845 - nornir.core.task -    ERROR -      start() - Host 'vMX1': task 'main_task' failed with traceback:
Traceback (most recent call last):
  File "/Users/sohanr/PycharmProjects/Nornir_Auto/venv/lib/python3.9/site-packages/nornir/core/task.py", line 99, in start
    r = self.task(self, **self.params)
  File "/Users/sohanr/PycharmProjects/Nornir_Auto/dashboard/dashboard.py", line 47, in main_task
    task.run(name='facts', task=pyez_facts)
  File "/Users/sohanr/PycharmProjects/Nornir_Auto/venv/lib/python3.9/site-packages/nornir/core/task.py", line 174, in run
    raise NornirSubTaskError(task=run_task, result=r)
nornir.core.exceptions.NornirSubTaskError: Subtask: facts (failed)


2022-09-28 22:27:59,845 - nornir.core.task -    ERROR -      start() - Host 'vMX2': task 'main_task' failed with traceback:
Traceback (most recent call last):
  File "/Users/sohanr/PycharmProjects/Nornir_Auto/venv/lib/python3.9/site-packages/nornir/core/task.py", line 99, in start
    r = self.task(self, **self.params)
  File "/Users/sohanr/PycharmProjects/Nornir_Auto/dashboard/dashboard.py", line 47, in main_task
    task.run(name='facts', task=pyez_facts)
  File "/Users/sohanr/PycharmProjects/Nornir_Auto/venv/lib/python3.9/site-packages/nornir/core/task.py", line 174, in run
    raise NornirSubTaskError(task=run_task, result=r)
nornir.core.exceptions.NornirSubTaskError: Subtask: facts (failed)


2022-11-11 12:11:44,013 -  nornir.core -     INFO -        run() - Running task 'main_task' with args {} on 3 hosts
2023-04-03 20:18:00,534 -  nornir.core -     INFO -        run() - Running task 'main_task' with args {} on 3 hosts
2023-04-03 20:51:03,623 -  nornir.core -     INFO -        run() - Running task 'pyez_rpc' with args {'func': 'get-bgp-summary-information'} on 3 hosts
2023-04-03 20:54:23,513 -  nornir.core -     INFO -        run() - Running task 'pyez_rpc' with args {'func': 'get-bgp-summary-information'} on 3 hosts
2023-04-03 21:12:39,799 -  nornir.core -     INFO -        run() - Running task 'main_task' with args {} on 3 hosts
2023-04-03 21:12:39,817 - nornir.core.task -    ERROR -      start() - Host 'vMX3': task 'main_task' failed with traceback:
Traceback (most recent call last):
  File "/Users/sohanr/PycharmProjects/Nornir_Auto/venv/lib/python3.9/site-packages/nornir/core/task.py", line 99, in start
    r = self.task(self, **self.params)
  File "<stdin>", line 6, in main_task
NameError: name 'pyez_facts' is not defined

2023-04-03 21:12:39,818 - nornir.core.task -    ERROR -      start() - Host 'vMX1': task 'main_task' failed with traceback:
Traceback (most recent call last):
  File "/Users/sohanr/PycharmProjects/Nornir_Auto/venv/lib/python3.9/site-packages/nornir/core/task.py", line 99, in start
    r = self.task(self, **self.params)
  File "<stdin>", line 6, in main_task
NameError: name 'pyez_facts' is not defined

2023-04-03 21:12:39,819 - nornir.core.task -    ERROR -      start() - Host 'vMX2': task 'main_task' failed with traceback:
Traceback (most recent call last):
  File "/Users/sohanr/PycharmProjects/Nornir_Auto/venv/lib/python3.9/site-packages/nornir/core/task.py", line 99, in start
    r = self.task(self, **self.params)
  File "<stdin>", line 6, in main_task
NameError: name 'pyez_facts' is not defined

2023-04-03 21:13:58,336 -  nornir.core -     INFO -        run() - Running task 'main_task' with args {} on 3 hosts
2023-04-03 21:14:32,485 -  nornir.core -     INFO -        run() - Running task 'main_task' with args {} on 3 hosts
